Workbook

Sheet Scoring Rules
A1: Outcome | B1: Points | C1: Potential points
A2: Correctly guessing Win/Loss/Draw of group game | B2: +1 | C2: 72
A3: Correctly guessing exact score of group game | B3: +2 | C3: 144
A4: Correctly picking group winner (A-L) | B4: +2 | C4: 24
A5: Correctly picking each non-winning group place | B5: +1 | C5: 36
A6: Correctly picking each team in Round of 16 | B6: +2 | C6: 32
A7: Correctly picking each team in Quarter-finals | B7: +4 | C7: 32
A8: Correctly picking each team in Semi-finals | B8: +8 | C8: 32
A9: Correctly picking each Final team | B9: +16 | C9: 32
A10: Correctly picking World Cup Winner | B10: +32 | C10: 32
A11: TOTAL | C11: =SUM(C2:C10) -> 436

Sheet Group Stage
A1: Match | B1: Group | C1: Home | D1: Away | E1: Home Goals | F1: Away Goals | G1: Result | I1: Self check
A2: 1 | B2: A | C2: Mexico | D2: South Korea | E2: 0 | F2: 0 | G2: =IF(AND(E2<>"",F2<>""),IF(E2>F2,C2,IF(E2<F2,D2,"Draw")),"") -> Draw | I2: Home | J2: {=SUMPRODUCT((G2:G73=C2:C73)*1)} -> 52
A3: 2 | B3: A | C3: South Africa | D3: Czechia | E3: 0 | F3: 1 | G3: =IF(AND(E3<>"",F3<>""),IF(E3>F3,C3,IF(E3<F3,D3,"Draw")),"") -> Czechia | I3: Away | J3: {=SUMPRODUCT((G2:G73=D2:D73)*1)} -> 7
A4: 3 | B4: A | C4: Mexico | D4: South Africa | E4: 2 | F4: 0 | G4: =IF(AND(E4<>"",F4<>""),IF(E4>F4,C4,IF(E4<F4,D4,"Draw")),"") -> Mexico | I4: Draw | J4: =COUNTIF(G2:G73,"Draw") -> 13
A5: 4 | B5: A | C5: South Korea | D5: Czechia | E5: 0 | F5: 0 | G5: =IF(AND(E5<>"",F5<>""),IF(E5>F5,C5,IF(E5<F5,D5,"Draw")),"") -> Draw | I5: TOTAL | J5: =SUM(J2:J4) -> 72
A6: 5 | B6: A | C6: Mexico | D6: Czechia | E6: 2 | F6: 0 | G6: =IF(AND(E6<>"",F6<>""),IF(E6>F6,C6,IF(E6<F6,D6,"Draw")),"") -> Mexico | I6: (should total 72)
A7: 6 | B7: A | C7: South Korea | D7: South Africa | E7: 1 | F7: 0 | G7: =IF(AND(E7<>"",F7<>""),IF(E7>F7,C7,IF(E7<F7,D7,"Draw")),"") -> South Korea
A8: 7 | B8: B | C8: Canada | D8: Switzerland | E8: 0 | F8: 0 | G8: =IF(AND(E8<>"",F8<>""),IF(E8>F8,C8,IF(E8<F8,D8,"Draw")),"") -> Draw
A9: 8 | B9: B | C9: Qatar | D9: Bosnia-Herzegovina | E9: 0 | F9: 1 | G9: =IF(AND(E9<>"",F9<>""),IF(E9>F9,C9,IF(E9<F9,D9,"Draw")),"") -> Bosnia-Herzegovina
A10: 9 | B10: B | C10: Canada | D10: Qatar | E10: 1 | F10: 0 | G10: =IF(AND(E10<>"",F10<>""),IF(E10>F10,C10,IF(E10<F10,D10,"Draw")),"") -> Canada
A11: 10 | B11: B | C11: Switzerland | D11: Bosnia-Herzegovina | E11: 1 | F11: 0 | G11: =IF(AND(E11<>"",F11<>""),IF(E11>F11,C11,IF(E11<F11,D11,"Draw")),"") -> Switzerland
A12: 11 | B12: B | C12: Canada | D12: Bosnia-Herzegovina | E12: 1 | F12: 0 | G12: =IF(AND(E12<>"",F12<>""),IF(E12>F12,C12,IF(E12<F12,D12,"Draw")),"") -> Canada
A13: 12 | B13: B | C13: Switzerland | D13: Qatar | E13: 2 | F13: 0 | G13: =IF(AND(E13<>"",F13<>""),IF(E13>F13,C13,IF(E13<F13,D13,"Draw")),"") -> Switzerland
A14: 13 | B14: C | C14: Brazil | D14: Morocco | E14: 1 | F14: 0 | G14: =IF(AND(E14<>"",F14<>""),IF(E14>F14,C14,IF(E14<F14,D14,"Draw")),"") -> Brazil
A15: 14 | B15: C | C15: Scotland | D15: Haiti | E15: 1 | F15: 0 | G15: =IF(AND(E15<>"",F15<>""),IF(E15>F15,C15,IF(E15<F15,D15,"Draw")),"") -> Scotland
A16: 15 | B16: C | C16: Brazil | D16: Scotland | E16: 1 | F16: 0 | G16: =IF(AND(E16<>"",F16<>""),IF(E16>F16,C16,IF(E16<F16,D16,"Draw")),"") -> Brazil
A17: 16 | B17: C | C17: Morocco | D17: Haiti | E17: 2 | F17: 0 | G17: =IF(AND(E17<>"",F17<>""),IF(E17>F17,C17,IF(E17<F17,D17,"Draw")),"") -> Morocco
A18: 17 | B18: C | C18: Brazil | D18: Haiti | E18: 3 | F18: 0 | G18: =IF(AND(E18<>"",F18<>""),IF(E18>F18,C18,IF(E18<F18,D18,"Draw")),"") -> Brazil
... A73: 72 | B73: L | C73: Croatia | D73: Panama | E73: 2 | F73: 0 | G73: =IF(AND(E73<>"",F73<>""),IF(E73>F73,C73,IF(E73<F73,D73,"Draw")),"") -> Croatia

Sheet Elimination Rounds
A1: Team | B1: Code | C1: Group | D1: Group Finish (1-4) | E1: Round of 16 | F1: Quarter-finals | G1: Semi-finals | H1: Final | I1: Winner | K1: Team | L1: Code | M1: Win | N1: D | O1: L | P1: Pts | Q1: GD | R1: GF | S1: Group Rank | U1: TEAM | V1: Code | W1: Win | X1: D | Y1: L | Z1: Pts | AA1: GD | AB1: GF | AC1: Group Rank | AF1: Team | AG1: Code | AH1: Win | AI1: D | AJ1: L | AK1: Pts | AL1: GD | AM1: GF | AN1: Group Rank | AP1: Team | AQ1: Code | AR1: Win | AS1: D | AT1: L | AU1: Pts | AV1: GD | AW1: GF | AX1: Group Rank
A2: Mexico | B2: =C2&D2 -> A1 | C2: A | D2: 1 | E2: 1 | K2: Mexico | L2: A | M2: {=SUMPRODUCT( (('Group Stage'!$C$2:$C$73=A2)*('Group Stage'!$E$2:$E$73>'Group Stage'!$F$2:$F$73))+ (('Group Stage'!$D$2:$D$73=A2)*('Group Stage'!$F$2:$F$73>'Group Stage'!$E$2:$E$73)) )} -> 2 | N2: {=SUMPRODUCT( (('Group Stage'!$C$2:$C$73=A2)*('Group Stage'!$E$2:$E$73='Group Stage'!$F$2:$F$73))+ (('Group Stage'!$D$2:$D$73=A2)*('Group Stage'!$F$2:$F$73='Group Stage'!$E$2:$E$73)) )} -> 1 | O2: {=SUMPRODUCT( (('Group Stage'!$C$2:$C$73=A2)*('Group Stage'!$E$2:$E$73<'Group Stage'!$F$2:$F$73))+ (('Group Stage'!$D$2:$D$73=A2)*('Group Stage'!$F$2:$F$73<'Group Stage'!$E$2:$E$73)) )} -> 0 | P2: {=SUMPRODUCT( (('Group Stage'!$C$2:$C$73=A2)*('Group Stage'!$E$2:$E$73>'Group Stage'!$F$2:$F$73))*3+ (('Group Stage'!$D$2:$D$73=A2)*('Group Stage'!$F$2:$F$73>'Group Stage'!$E$2:$E$73))*3+ (('Group Stage'!$C$2:$C$73=A2)*('Group Stage'!$E$2:$E$73='Group Stage'!$F$2:$F$73))*1+ (('Group Stage'!$D$2:$D$73=A2)*('Group Stage'!$F$2:$F$73='Group Stage'!$E$2:$E$73))*1 )} -> 7 | Q2: {=SUMPRODUCT( ('Group Stage'!$C$2:$C$73=A2)*('Group Stage'!$E$2:$E$73-'Group Stage'!$F$2:$F$73)+ ('Group Stage'!$D$2:$D$73=A2)*('Group Stage'!$F$2:$F$73-'Group Stage'!$E$2:$E$73) )} -> 4 | R2: {=SUMPRODUCT( ('Group Stage'!$C$2:$C$73=A2)*'Group Stage'!$E$2:$E$73+ ('Group Stage'!$D$2:$D$73=A2)*'Group Stage'!$F$2:$F$73 )} -> 4 | S2: {=SUMPRODUCT( (('Elimination Rounds'!$L$2:$L$49=L2)* (('Elimination Rounds'!$P$2:$P$49>P2)+ ('Elimination Rounds'!$P$2:$P$49=P2)*('Elimination Rounds'!$Q$2:$Q$49>Q2)+ ('Elimination Rounds'!$P$2:$P$49=P2)*('Elimination Rounds'!$Q$2:$Q$49=Q2)*('Elimination Rounds'!$R$2:$R$49>R2))) )+1} -> 1 | U2: {=_xlfn._xlws.SORT('Elimination Rounds'!$K$2:$S$49,{2,9},1)} -> Mexico | V2: A | W2: 2 | X2: 1 | Y2: 0 | Z2: 7 | AA2: 4 | AB2: 4 | AC2: 1 | AF2: =U2 -> Mexico | AG2: =V2 -> A | AH2: =W2 -> 2 | AI2: =X2 -> 1 | AJ2: =Y2 -> 0 | AK2: =Z2 -> 7 | AL2: =AA2 -> 4 | AM2: =AB2 -> 4 | AN2: =AC2 -> 1 | AP2: =U34 -> France | AQ2: =V34 -> I | AR2: =W34 -> 3 | AS2: =X34 -> 0 | AT2: =Y34 -> 0 | AU2: =Z34 -> 9 | AV2: =AA34 -> 6 | AW2: =AB34 -> 6 | AX2: =AC34 -> 1
A3: South Korea | B3: =C3&D3 -> A2 | C3: A | D3: 2 | K3: South Korea | L3: A | M3: {=SUMPRODUCT( (('Group Stage'!$C$2:$C$73=A3)*('Group Stage'!$E$2:$E$73>'Group Stage'!$F$2:$F$73))+ (('Group Stage'!$D$2:$D$73=A3)*('Group Stage'!$F$2:$F$73>'Group Stage'!$E$2:$E$73)) )} -> 1 | N3: {=SUMPRODUCT( (('Group Stage'!$C$2:$C$73=A3)*('Group Stage'!$E$2:$E$73='Group Stage'!$F$2:$F$73))+ (('Group Stage'!$D$2:$D$73=A3)*('Group Stage'!$F$2:$F$73='Group Stage'!$E$2:$E$73)) )} -> 2 | O3: {=SUMPRODUCT( (('Group Stage'!$C$2:$C$73=A3)*('Group Stage'!$E$2:$E$73<'Group Stage'!$F$2:$F$73))+ (('Group Stage'!$D$2:$D$73=A3)*('Group Stage'!$F$2:$F$73<'Group Stage'!$E$2:$E$73)) )} -> 0 | P3: {=SUMPRODUCT( (('Group Stage'!$C$2:$C$73=A3)*('Group Stage'!$E$2:$E$73>'Group Stage'!$F$2:$F$73))*3+ (('Group Stage'!$D$2:$D$73=A3)*('Group Stage'!$F$2:$F$73>'Group Stage'!$E$2:$E$73))*3+ (('Group Stage'!$C$2:$C$73=A3)*('Group Stage'!$E$2:$E$73='Group Stage'!$F$2:$F$73))*1+ (('Group Stage'!$D$2:$D$73=A3)*('Group Stage'!$F$2:$F$73='Group Stage'!$E$2:$E$73))*1 )} -> 5 | Q3: {=SUMPRODUCT( ('Group Stage'!$C$2:$C$73=A3)*('Group Stage'!$E$2:$E$73-'Group Stage'!$F$2:$F$73)+ ('Group Stage'!$D$2:$D$73=A3)*('Group Stage'!$F$2:$F$73-'Group Stage'!$E$2:$E$73) )} -> 1 | R3: {=SUMPRODUCT( ('Group Stage'!$C$2:$C$73=A3)*'Group Stage'!$E$2:$E$73+ ('Group Stage'!$D$2:$D$73=A3)*'Group Stage'!$F$2:$F$73 )} -> 1 | S3: {=SUMPRODUCT( (('Elimination Rounds'!$L$2:$L$49=L3)* (('Elimination Rounds'!$P$2:$P$49>P3)+ ('Elimination Rounds'!$P$2:$P$49=P3)*('Elimination Rounds'!$Q$2:$Q$49>Q3)+ ('Elimination Rounds'!$P$2:$P$49=P3)*('Elimination Rounds'!$Q$2:$Q$49=Q3)*('Elimination Rounds'!$R$2:$R$49>R3))) )+1} -> 2 | U3: South Korea | V3: A | W3: 1 | X3: 2 | Y3: 0 | Z3: 5 | AA3: 1 | AB3: 1 | AC3: 2 | AF3: =U3 -> South Korea | AG3: =V3 -> A | AH3: =W3 -> 1 | AI3: =X3 -> 2 | AJ3: =Y3 -> 0 | AK3: =Z3 -> 5 | AL3: =AA3 -> 1 | AM3: =AB3 -> 1 | AN3: =AC3 -> 2 | AP3: =U35 -> Norway | AQ3: =V35 -> I | AR3: =W35 -> 1 | AS3: =X35 -> 1 | AT3: =Y35 -> 1 | AU3: =Z35 -> 4 | AV3: =AA35 -> 0 | AW3: =AB35 -> 3 | AX3: =AC35 -> 2
A4: South Africa | B4: =C4&D4 -> A4 | C4: A | D4: 4 | K4: South Africa | L4: A | M4: {=SUMPRODUCT( (('Group Stage'!$C$2:$C$73=A4)*('Group Stage'!$E$2:$E$73>'Group Stage'!$F$2:$F$73))+ (('Group Stage'!$D$2:$D$73=A4)*('Group Stage'!$F$2:$F$73>'Group Stage'!$E$2:$E$73)) )} -> 0 | N4: {=SUMPRODUCT( (('Group Stage'!$C$2:$C$73=A4)*('Group Stage'!$E$2:$E$73='Group Stage'!$F$2:$F$73))+ (('Group Stage'!$D$2:$D$73=A4)*('Group Stage'!$F$2:$F$73='Group Stage'!$E$2:$E$73)) )} -> 0 | O4: {=SUMPRODUCT( (('Group Stage'!$C$2:$C$73=A4)*('Group Stage'!$E$2:$E$73<'Group Stage'!$F$2:$F$73))+ (('Group Stage'!$D$2:$D$73=A4)*('Group Stage'!$F$2:$F$73<'Group Stage'!$E$2:$E$73)) )} -> 3 | P4: {=SUMPRODUCT( (('Group Stage'!$C$2:$C$73=A4)*('Group Stage'!$E$2:$E$73>'Group Stage'!$F$2:$F$73))*3+ (('Group Stage'!$D$2:$D$73=A4)*('Group Stage'!$F$2:$F$73>'Group Stage'!$E$2:$E$73))*3+ (('Group Stage'!$C$2:$C$73=A4)*('Group Stage'!$E$2:$E$73='Group Stage'!$F$2:$F$73))*1+ (('Group Stage'!$D$2:$D$73=A4)*('Group Stage'!$F$2:$F$73='Group Stage'!$E$2:$E$73))*1 )} -> 0 | Q4: {=SUMPRODUCT( ('Group Stage'!$C$2:$C$73=A4)*('Group Stage'!$E$2:$E$73-'Group Stage'!$F$2:$F$73)+ ('Group Stage'!$D$2:$D$73=A4)*('Group Stage'!$F$2:$F$73-'Group Stage'!$E$2:$E$73) )} -> -4 | R4: {=SUMPRODUCT( ('Group Stage'!$C$2:$C$73=A4)*'Group Stage'!$E$2:$E$73+ ('Group Stage'!$D$2:$D$73=A4)*'Group Stage'!$F$2:$F$73 )} -> 0 | S4: {=SUMPRODUCT( (('Elimination Rounds'!$L$2:$L$49=L4)* (('Elimination Rounds'!$P$2:$P$49>P4)+ ('Elimination Rounds'!$P$2:$P$49=P4)*('Elimination Rounds'!$Q$2:$Q$49>Q4)+ ('Elimination Rounds'!$P$2:$P$49=P4)*('Elimination Rounds'!$Q$2:$Q$49=Q4)*('Elimination Rounds'!$R$2:$R$49>R4))) )+1} -> 4 | U4: Czechia | V4: A | W4: 1 | X4: 1 | Y4: 1 | Z4: 4 | AA4: -1 | AB4: 1 | AC4: 3 | AF4: =U4 -> Czechia | AG4: =V4 -> A | AH4: =W4 -> 1 | AI4: =X4 -> 1 | AJ4: =Y4 -> 1 | AK4: =Z4 -> 4 | AL4: =AA4 -> -1 | AM4: =AB4 -> 1 | AN4: =AC4 -> 3 | AP4: =U36 -> Senegal | AQ4: =V36 -> I | AR4: =W36 -> 1 | AS4: =X36 -> 1 | AT4: =Y36 -> 1 | AU4: =Z36 -> 4 | AV4: =AA36 -> -1 | AW4: =AB36 -> 2 | AX4: =AC36 -> 3
A5: Czechia | B5: =C5&D5 -> A3 | C5: A | D5: 3 | K5: Czechia | L5: A | M5: {=SUMPRODUCT( (('Group Stage'!$C$2:$C$73=A5)*('Group Stage'!$E$2:$E$73>'Group Stage'!$F$2:$F$73))+ (('Group Stage'!$D$2:$D$73=A5)*('Group Stage'!$F$2:$F$73>'Group Stage'!$E$2:$E$73)) )} -> 1 | N5: {=SUMPRODUCT( (('Group Stage'!$C$2:$C$73=A5)*('Group Stage'!$E$2:$E$73='Group Stage'!$F$2:$F$73))+ (('Group Stage'!$D$2:$D$73=A5)*('Group Stage'!$F$2:$F$73='Group Stage'!$E$2:$E$73)) )} -> 1 | O5: {=SUMPRODUCT( (('Group Stage'!$C$2:$C$73=A5)*('Group Stage'!$E$2:$E$73<'Group Stage'!$F$2:$F$73))+ (('Group Stage'!$D$2:$D$73=A5)*('Group Stage'!$F$2:$F$73<'Group Stage'!$E$2:$E$73)) )} -> 1 | P5: {=SUMPRODUCT( (('Group Stage'!$C$2:$C$73=A5)*('Group Stage'!$E$2:$E$73>'Group Stage'!$F$2:$F$73))*3+ (('Group Stage'!$D$2:$D$73=A5)*('Group Stage'!$F$2:$F$73>'Group Stage'!$E$2:$E$73))*3+ (('Group Stage'!$C$2:$C$73=A5)*('Group Stage'!$E$2:$E$73='Group Stage'!$F$2:$F$73))*1+ (('Group Stage'!$D$2:$D$73=A5)*('Group Stage'!$F$2:$F$73='Group Stage'!$E$2:$E$73))*1 )} -> 4 | Q5: {=SUMPRODUCT( ('Group Stage'!$C$2:$C$73=A5)*('Group Stage'!$E$2:$E$73-'Group Stage'!$F$2:$F$73)+ ('Group Stage'!$D$2:$D$73=A5)*('Group Stage'!$F$2:$F$73-'Group Stage'!$E$2:$E$73) )} -> -1 | R5: {=SUMPRODUCT( ('Group Stage'!$C$2:$C$73=A5)*'Group Stage'!$E$2:$E$73+ ('Group Stage'!$D$2:$D$73=A5)*'Group Stage'!$F$2:$F$73 )} -> 1 | S5: {=SUMPRODUCT( (('Elimination Rounds'!$L$2:$L$49=L5)* (('Elimination Rounds'!$P$2:$P$49>P5)+ ('Elimination Rounds'!$P$2:$P$49=P5)*('Elimination Rounds'!$Q$2:$Q$49>Q5)+ ('Elimination Rounds'!$P$2:$P$49=P5)*('Elimination Rounds'!$Q$2:$Q$49=Q5)*('Elimination Rounds'!$R$2:$R$49>R5))) )+1} -> 3 | U5: South Africa | V5: A | W5: 0 | X5: 0 | Y5: 3 | Z5: 0 | AA5: -4 | AB5: 0 | AC5: 4 | AF5: =U5 -> South Africa | AG5: =V5 -> A | AH5: =W5 -> 0 | AI5: =X5 -> 0 | AJ5: =Y5 -> 3 | AK5: =Z5 -> 0 | AL5: =AA5 -> -4 | AM5: =AB5 -> 0 | AN5: =AC5 -> 4 | AP5: =U37 -> Iraq | AQ5: =V37 -> I | AR5: =W37 -> 0 | AS5: =X37 -> 0 | AT5: =Y37 -> 3 | AU5: =Z37 -> 0 | AV5: =AA37 -> -5 | AW5: =AB37 -> 0 | AX5: =AC37 -> 4
A6: Canada | B6: =C6&D6 -> B2 | C6: B | D6: 2 | E6: 1 | K6: Canada | L6: B | M6: {=SUMPRODUCT( (('Group Stage'!$C$2:$C$73=A6)*('Group Stage'!$E$2:$E$73>'Group Stage'!$F$2:$F$73))+ (('Group Stage'!$D$2:$D$73=A6)*('Group Stage'!$F$2:$F$73>'Group Stage'!$E$2:$E$73)) )} -> 2 | N6: {=SUMPRODUCT( (('Group Stage'!$C$2:$C$73=A6)*('Group Stage'!$E$2:$E$73='Group Stage'!$F$2:$F$73))+ (('Group Stage'!$D$2:$D$73=A6)*('Group Stage'!$F$2:$F$73='Group Stage'!$E$2:$E$73)) )} -> 1 | O6: {=SUMPRODUCT( (('Group Stage'!$C$2:$C$73=A6)*('Group Stage'!$E$2:$E$73<'Group Stage'!$F$2:$F$73))+ (('Group Stage'!$D$2:$D$73=A6)*('Group Stage'!$F$2:$F$73<'Group Stage'!$E$2:$E$73)) )} -> 0 | P6: {=SUMPRODUCT( (('Group Stage'!$C$2:$C$73=A6)*('Group Stage'!$E$2:$E$73>'Group Stage'!$F$2:$F$73))*3+ (('Group Stage'!$D$2:$D$73=A6)*('Group Stage'!$F$2:$F$73>'Group Stage'!$E$2:$E$73))*3+ (('Group Stage'!$C$2:$C$73=A6)*('Group Stage'!$E$2:$E$73='Group Stage'!$F$2:$F$73))*1+ (('Group Stage'!$D$2:$D$73=A6)*('Group Stage'!$F$2:$F$73='Group Stage'!$E$2:$E$73))*1 )} -> 7 | Q6: {=SUMPRODUCT( ('Group Stage'!$C$2:$C$73=A6)*('Group Stage'!$E$2:$E$73-'Group Stage'!$F$2:$F$73)+ ('Group Stage'!$D$2:$D$73=A6)*('Group Stage'!$F$2:$F$73-'Group Stage'!$E$2:$E$73) )} -> 2 | R6: {=SUMPRODUCT( ('Group Stage'!$C$2:$C$73=A6)*'Group Stage'!$E$2:$E$73+ ('Group Stage'!$D$2:$D$73=A6)*'Group Stage'!$F$2:$F$73 )} -> 2 | S6: {=SUMPRODUCT( (('Elimination Rounds'!$L$2:$L$49=L6)* (('Elimination Rounds'!$P$2:$P$49>P6)+ ('Elimination Rounds'!$P$2:$P$49=P6)*('Elimination Rounds'!$Q$2:$Q$49>Q6)+ ('Elimination Rounds'!$P$2:$P$49=P6)*('Elimination Rounds'!$Q$2:$Q$49=Q6)*('Elimination Rounds'!$R$2:$R$49>R6))) )+1} -> 2 | U6: Switzerland | V6: B | W6: 2 | X6: 1 | Y6: 0 | Z6: 7 | AA6: 3 | AB6: 3 | AC6: 1
A7: Switzerland | B7: =C7&D7 -> B1 | C7: B | D7: 1 | K7: Switzerland | L7: B | M7: {=SUMPRODUCT( (('Group Stage'!$C$2:$C$73=A7)*('Group Stage'!$E$2:$E$73>'Group Stage'!$F$2:$F$73))+ (('Group Stage'!$D$2:$D$73=A7)*('Group Stage'!$F$2:$F$73>'Group Stage'!$E$2:$E$73)) )} -> 2 | N7: {=SUMPRODUCT( (('Group Stage'!$C$2:$C$73=A7)*('Group Stage'!$E$2:$E$73='Group Stage'!$F$2:$F$73))+ (('Group Stage'!$D$2:$D$73=A7)*('Group Stage'!$F$2:$F$73='Group Stage'!$E$2:$E$73)) )} -> 1 | O7: {=SUMPRODUCT( (('Group Stage'!$C$2:$C$73=A7)*('Group Stage'!$E$2:$E$73<'Group Stage'!$F$2:$F$73))+ (('Group Stage'!$D$2:$D$73=A7)*('Group Stage'!$F$2:$F$73<'Group Stage'!$E$2:$E$73)) )} -> 0 | P7: {=SUMPRODUCT( (('Group Stage'!$C$2:$C$73=A7)*('Group Stage'!$E$2:$E$73>'Group Stage'!$F$2:$F$73))*3+ (('Group Stage'!$D$2:$D$73=A7)*('Group Stage'!$F$2:$F$73>'Group Stage'!$E$2:$E$73))*3+ (('Group Stage'!$C$2:$C$73=A7)*('Group Stage'!$E$2:$E$73='Group Stage'!$F$2:$F$73))*1+ (('Group Stage'!$D$2:$D$73=A7)*('Group Stage'!$F$2:$F$73='Group Stage'!$E$2:$E$73))*1 )} -> 7 | Q7: {=SUMPRODUCT( ('Group Stage'!$C$2:$C$73=A7)*('Group Stage'!$E$2:$E$73-'Group Stage'!$F$2:$F$73)+ ('Group Stage'!$D$2:$D$73=A7)*('Group Stage'!$F$2:$F$73-'Group Stage'!$E$2:$E$73) )} -> 3 | R7: {=SUMPRODUCT( ('Group Stage'!$C$2:$C$73=A7)*'Group Stage'!$E$2:$E$73+ ('Group Stage'!$D$2:$D$73=A7)*'Group Stage'!$F$2:$F$73 )} -> 3 | S7: {=SUMPRODUCT( (('Elimination Rounds'!$L$2:$L$49=L7)* (('Elimination Rounds'!$P$2:$P$49>P7)+ ('Elimination Rounds'!$P$2:$P$49=P7)*('Elimination Rounds'!$Q$2:$Q$49>Q7)+ ('Elimination Rounds'!$P$2:$P$49=P7)*('Elimination Rounds'!$Q$2:$Q$49=Q7)*('Elimination Rounds'!$R$2:$R$49>R7))) )+1} -> 1 | U7: Canada | V7: B | W7: 2 | X7: 1 | Y7: 0 | Z7: 7 | AA7: 2 | AB7: 2 | AC7: 2 | AF7: Team | AG7: Code | AH7: Win | AI7: D | AJ7: L | AK7: Pts | AL7: GD | AM7: GF | AN7: Group Rank | AP7: Team | AQ7: Code | AR7: Win | AS7: D | AT7: L | AU7: Pts | AV7: GD | AW7: GF | AX7: Group Rank
A8: Qatar | B8: =C8&D8 -> B4 | C8: B | D8: 4 | K8: Qatar | L8: B | M8: {=SUMPRODUCT( (('Group Stage'!$C$2:$C$73=A8)*('Group Stage'!$E$2:$E$73>'Group Stage'!$F$2:$F$73))+ (('Group Stage'!$D$2:$D$73=A8)*('Group Stage'!$F$2:$F$73>'Group Stage'!$E$2:$E$73)) )} -> 0 | N8: {=SUMPRODUCT( (('Group Stage'!$C$2:$C$73=A8)*('Group Stage'!$E$2:$E$73='Group Stage'!$F$2:$F$73))+ (('Group Stage'!$D$2:$D$73=A8)*('Group Stage'!$F$2:$F$73='Group Stage'!$E$2:$E$73)) )} -> 0 | O8: {=SUMPRODUCT( (('Group Stage'!$C$2:$C$73=A8)*('Group Stage'!$E$2:$E$73<'Group Stage'!$F$2:$F$73))+ (('Group Stage'!$D$2:$D$73=A8)*('Group Stage'!$F$2:$F$73<'Group Stage'!$E$2:$E$73)) )} -> 3 | P8: {=SUMPRODUCT( (('Group Stage'!$C$2:$C$73=A8)*('Group Stage'!$E$2:$E$73>'Group Stage'!$F$2:$F$73))*3+ (('Group Stage'!$D$2:$D$73=A8)*('Group Stage'!$F$2:$F$73>'Group Stage'!$E$2:$E$73))*3+ (('Group Stage'!$C$2:$C$73=A8)*('Group Stage'!$E$2:$E$73='Group Stage'!$F$2:$F$73))*1+ (('Group Stage'!$D$2:$D$73=A8)*('Group Stage'!$F$2:$F$73='Group Stage'!$E$2:$E$73))*1 )} -> 0 | Q8: {=SUMPRODUCT( ('Group Stage'!$C$2:$C$73=A8)*('Group Stage'!$E$2:$E$73-'Group Stage'!$F$2:$F$73)+ ('Group Stage'!$D$2:$D$73=A8)*('Group Stage'!$F$2:$F$73-'Group Stage'!$E$2:$E$73) )} -> -4 | R8: {=SUMPRODUCT( ('Group Stage'!$C$2:$C$73=A8)*'Group Stage'!$E$2:$E$73+ ('Group Stage'!$D$2:$D$73=A8)*'Group Stage'!$F$2:$F$73 )} -> 0 | S8: {=SUMPRODUCT( (('Elimination Rounds'!$L$2:$L$49=L8)* (('Elimination Rounds'!$P$2:$P$49>P8)+ ('Elimination Rounds'!$P$2:$P$49=P8)*('Elimination Rounds'!$Q$2:$Q$49>Q8)+ ('Elimination Rounds'!$P$2:$P$49=P8)*('Elimination Rounds'!$Q$2:$Q$49=Q8)*('Elimination Rounds'!$R$2:$R$49>R8))) )+1} -> 4 | U8: Bosnia-Herzegovina | V8: B | W8: 1 | X8: 0 | Y8: 2 | Z8: 3 | AA8: -1 | AB8: 1 | AC8: 3 | AF8: =U6 -> Switzerland | AG8: =V6 -> B | AH8: =W6 -> 2 | AI8: =X6 -> 1 | AJ8: =Y6 -> 0 | AK8: =Z6 -> 7 | AL8: =AA6 -> 3 | AM8: =AB6 -> 3 | AN8: =AC6 -> 1 | AP8: =U38 -> Argentina | AQ8: =V38 -> J | AR8: =W38 -> 3 | AS8: =X38 -> 0 | AT8: =Y38 -> 0 | AU8: =Z38 -> 9 | AV8: =AA38 -> 6 | AW8: =AB38 -> 6 | AX8: =AC38 -> 1
A9: Bosnia-Herzegovina | B9: =C9&D9 -> B3 | C9: B | D9: 3 | K9: Bosnia-Herzegovina | L9: B | M9: {=SUMPRODUCT( (('Group Stage'!$C$2:$C$73=A9)*('Group Stage'!$E$2:$E$73>'Group Stage'!$F$2:$F$73))+ (('Group Stage'!$D$2:$D$73=A9)*('Group Stage'!$F$2:$F$73>'Group Stage'!$E$2:$E$73)) )} -> 1 | N9: {=SUMPRODUCT( (('Group Stage'!$C$2:$C$73=A9)*('Group Stage'!$E$2:$E$73='Group Stage'!$F$2:$F$73))+ (('Group Stage'!$D$2:$D$73=A9)*('Group Stage'!$F$2:$F$73='Group Stage'!$E$2:$E$73)) )} -> 0 | O9: {=SUMPRODUCT( (('Group Stage'!$C$2:$C$73=A9)*('Group Stage'!$E$2:$E$73<'Group Stage'!$F$2:$F$73))+ (('Group Stage'!$D$2:$D$73=A9)*('Group Stage'!$F$2:$F$73<'Group Stage'!$E$2:$E$73)) )} -> 2 | P9: {=SUMPRODUCT( (('Group Stage'!$C$2:$C$73=A9)*('Group Stage'!$E$2:$E$73>'Group Stage'!$F$2:$F$73))*3+ (('Group Stage'!$D$2:$D$73=A9)*('Group Stage'!$F$2:$F$73>'Group Stage'!$E$2:$E$73))*3+ (('Group Stage'!$C$2:$C$73=A9)*('Group Stage'!$E$2:$E$73='Group Stage'!$F$2:$F$73))*1+ (('Group Stage'!$D$2:$D$73=A9)*('Group Stage'!$F$2:$F$73='Group Stage'!$E$2:$E$73))*1 )} -> 3 | Q9: {=SUMPRODUCT( ('Group Stage'!$C$2:$C$73=A9)*('Group Stage'!$E$2:$E$73-'Group Stage'!$F$2:$F$73)+ ('Group Stage'!$D$2:$D$73=A9)*('Group Stage'!$F$2:$F$73-'Group Stage'!$E$2:$E$73) )} -> -1 | R9: {=SUMPRODUCT( ('Group Stage'!$C$2:$C$73=A9)*'Group Stage'!$E$2:$E$73+ ('Group Stage'!$D$2:$D$73=A9)*'Group Stage'!$F$2:$F$73 )} -> 1 | S9: {=SUMPRODUCT( (('Elimination Rounds'!$L$2:$L$49=L9)* (('Elimination Rounds'!$P$2:$P$49>P9)+ ('Elimination Rounds'!$P$2:$P$49=P9)*('Elimination Rounds'!$Q$2:$Q$49>Q9)+ ('Elimination Rounds'!$P$2:$P$49=P9)*('Elimination Rounds'!$Q$2:$Q$49=Q9)*('Elimination Rounds'!$R$2:$R$49>R9))) )+1} -> 3 | U9: Qatar | V9: B | W9: 0 | X9: 0 | Y9: 3 | Z9: 0 | AA9: -4 | AB9: 0 | AC9: 4 | AF9: =U7 -> Canada | AG9: =V7 -> B | AH9: =W7 -> 2 | AI9: =X7 -> 1 | AJ9: =Y7 -> 0 | AK9: =Z7 -> 7 | AL9: =AA7 -> 2 | AM9: =AB7 -> 2 | AN9: =AC7 -> 2 | AP9: =U39 -> Austria | AQ9: =V39 -> J | AR9: =W39 -> 2 | AS9: =X39 -> 0 | AT9: =Y39 -> 1 | AU9: =Z39 -> 6 | AV9: =AA39 -> 1 | AW9: =AB39 -> 2 | AX9: =AC39 -> 2
A10: Brazil | B10: =C10&D10 -> C1 | C10: C | D10: 1 | E10: 1 | F10: 1 | G10: 1 | K10: Brazil | L10: C | M10: {=SUMPRODUCT( (('Group Stage'!$C$2:$C$73=A10)*('Group Stage'!$E$2:$E$73>'Group Stage'!$F$2:$F$73))+ (('Group Stage'!$D$2:$D$73=A10)*('Group Stage'!$F$2:$F$73>'Group Stage'!$E$2:$E$73)) )} -> 3 | N10: {=SUMPRODUCT( (('Group Stage'!$C$2:$C$73=A10)*('Group Stage'!$E$2:$E$73='Group Stage'!$F$2:$F$73))+ (('Group Stage'!$D$2:$D$73=A10)*('Group Stage'!$F$2:$F$73='Group Stage'!$E$2:$E$73)) )} -> 0 | O10: {=SUMPRODUCT( (('Group Stage'!$C$2:$C$73=A10)*('Group Stage'!$E$2:$E$73<'Group Stage'!$F$2:$F$73))+ (('Group Stage'!$D$2:$D$73=A10)*('Group Stage'!$F$2:$F$73<'Group Stage'!$E$2:$E$73)) )} -> 0 | P10: {=SUMPRODUCT( (('Group Stage'!$C$2:$C$73=A10)*('Group Stage'!$E$2:$E$73>'Group Stage'!$F$2:$F$73))*3+ (('Group Stage'!$D$2:$D$73=A10)*('Group Stage'!$F$2:$F$73>'Group Stage'!$E$2:$E$73))*3+ (('Group Stage'!$C$2:$C$73=A10)*('Group Stage'!$E$2:$E$73='Group Stage'!$F$2:$F$73))*1+ (('Group Stage'!$D$2:$D$73=A10)*('Group Stage'!$F$2:$F$73='Group Stage'!$E$2:$E$73))*1 )} -> 9 | Q10: {=SUMPRODUCT( ('Group Stage'!$C$2:$C$73=A10)*('Group Stage'!$E$2:$E$73-'Group Stage'!$F$2:$F$73)+ ('Group Stage'!$D$2:$D$73=A10)*('Group Stage'!$F$2:$F$73-'Group Stage'!$E$2:$E$73) )} -> 5 | R10: {=SUMPRODUCT( ('Group Stage'!$C$2:$C$73=A10)*'Group Stage'!$E$2:$E$73+ ('Group Stage'!$D$2:$D$73=A10)*'Group Stage'!$F$2:$F$73 )} -> 5 | S10: {=SUMPRODUCT( (('Elimination Rounds'!$L$2:$L$49=L10)* (('Elimination Rounds'!$P$2:$P$49>P10)+ ('Elimination Rounds'!$P$2:$P$49=P10)*('Elimination Rounds'!$Q$2:$Q$49>Q10)+ ('Elimination Rounds'!$P$2:$P$49=P10)*('Elimination Rounds'!$Q$2:$Q$49=Q10)*('Elimination Rounds'!$R$2:$R$49>R10))) )+1} -> 1 | U10: Brazil | V10: C | W10: 3 | X10: 0 | Y10: 0 | Z10: 9 | AA10: 5 | AB10: 5 | AC10: 1 | AF10: =U8 -> Bosnia-Herzegovina | AG10: =V8 -> B | AH10: =W8 -> 1 | AI10: =X8 -> 0 | AJ10: =Y8 -> 2 | AK10: =Z8 -> 3 | AL10: =AA8 -> -1 | AM10: =AB8 -> 1 | AN10: =AC8 -> 3 | AP10: =U40 -> Algeria | AQ10: =V40 -> J | AR10: =W40 -> 1 | AS10: =X40 -> 0 | AT10: =Y40 -> 2 | AU10: =Z40 -> 3 | AV10: =AA40 -> -1 | AW10: =AB40 -> 2 | AX10: =AC40 -> 3
A11: Morocco | B11: =C11&D11 -> C2 | C11: C | D11: 2 | K11: Morocco | L11: C | M11: {=SUMPRODUCT( (('Group Stage'!$C$2:$C$73=A11)*('Group Stage'!$E$2:$E$73>'Group Stage'!$F$2:$F$73))+ (('Group Stage'!$D$2:$D$73=A11)*('Group Stage'!$F$2:$F$73>'Group Stage'!$E$2:$E$73)) )} -> 1 | N11: {=SUMPRODUCT( (('Group Stage'!$C$2:$C$73=A11)*('Group Stage'!$E$2:$E$73='Group Stage'!$F$2:$F$73))+ (('Group Stage'!$D$2:$D$73=A11)*('Group Stage'!$F$2:$F$73='Group Stage'!$E$2:$E$73)) )} -> 1 | O11: {=SUMPRODUCT( (('Group Stage'!$C$2:$C$73=A11)*('Group Stage'!$E$2:$E$73<'Group Stage'!$F$2:$F$73))+ (('Group Stage'!$D$2:$D$73=A11)*('Group Stage'!$F$2:$F$73<'Group Stage'!$E$2:$E$73)) )} -> 1 | P11: {=SUMPRODUCT( (('Group Stage'!$C$2:$C$73=A11)*('Group Stage'!$E$2:$E$73>'Group Stage'!$F$2:$F$73))*3+ (('Group Stage'!$D$2:$D$73=A11)*('Group Stage'!$F$2:$F$73>'Group Stage'!$E$2:$E$73))*3+ (('Group Stage'!$C$2:$C$73=A11)*('Group Stage'!$E$2:$E$73='Group Stage'!$F$2:$F$73))*1+ (('Group Stage'!$D$2:$D$73=A11)*('Group Stage'!$F$2:$F$73='Group Stage'!$E$2:$E$73))*1 )} -> 4 | Q11: {=SUMPRODUCT( ('Group Stage'!$C$2:$C$73=A11)*('Group Stage'!$E$2:$E$73-'Group Stage'!$F$2:$F$73)+ ('Group Stage'!$D$2:$D$73=A11)*('Group Stage'!$F$2:$F$73-'Group Stage'!$E$2:$E$73) )} -> 1 | R11: {=SUMPRODUCT( ('Group Stage'!$C$2:$C$73=A11)*'Group Stage'!$E$2:$E$73+ ('Group Stage'!$D$2:$D$73=A11)*'Group Stage'!$F$2:$F$73 )} -> 3 | S11: {=SUMPRODUCT( (('Elimination Rounds'!$L$2:$L$49=L11)* (('Elimination Rounds'!$P$2:$P$49>P11)+ ('Elimination Rounds'!$P$2:$P$49=P11)*('Elimination Rounds'!$Q$2:$Q$49>Q11)+ ('Elimination Rounds'!$P$2:$P$49=P11)*('Elimination Rounds'!$Q$2:$Q$49=Q11)*('Elimination Rounds'!$R$2:$R$49>R11))) )+1} -> 2 | U11: Morocco | V11: C | W11: 1 | X11: 1 | Y11: 1 | Z11: 4 | AA11: 1 | AB11: 3 | AC11: 2 | AF11: =U9 -> Qatar | AG11: =V9 -> B | AH11: =W9 -> 0 | AI11: =X9 -> 0 | AJ11: =Y9 -> 3 | AK11: =Z9 -> 0 | AL11: =AA9 -> -4 | AM11: =AB9 -> 0 | AN11: =AC9 -> 4 | AP11: =U41 -> Jordan | AQ11: =V41 -> J | AR11: =W41 -> 0 | AS11: =X41 -> 0 | AT11: =Y41 -> 3 | AU11: =Z41 -> 0 | AV11: =AA41 -> -6 | AW11: =AB41 -> 0 | AX11: =AC41 -> 4
A12: Scotland | B12: =C12&D12 -> C3 | C12: C | D12: 3 | K12: Scotland | L12: C | M12: {=SUMPRODUCT( (('Group Stage'!$C$2:$C$73=A12)*('Group Stage'!$E$2:$E$73>'Group Stage'!$F$2:$F$73))+ (('Group Stage'!$D$2:$D$73=A12)*('Group Stage'!$F$2:$F$73>'Group Stage'!$E$2:$E$73)) )} -> 1 | N12: {=SUMPRODUCT( (('Group Stage'!$C$2:$C$73=A12)*('Group Stage'!$E$2:$E$73='Group Stage'!$F$2:$F$73))+ (('Group Stage'!$D$2:$D$73=A12)*('Group Stage'!$F$2:$F$73='Group Stage'!$E$2:$E$73)) )} -> 1 | O12: {=SUMPRODUCT( (('Group Stage'!$C$2:$C$73=A12)*('Group Stage'!$E$2:$E$73<'Group Stage'!$F$2:$F$73))+ (('Group Stage'!$D$2:$D$73=A12)*('Group Stage'!$F$2:$F$73<'Group Stage'!$E$2:$E$73)) )} -> 1 | P12: {=SUMPRODUCT( (('Group Stage'!$C$2:$C$73=A12)*('Group Stage'!$E$2:$E$73>'Group Stage'!$F$2:$F$73))*3+ (('Group Stage'!$D$2:$D$73=A12)*('Group Stage'!$F$2:$F$73>'Group Stage'!$E$2:$E$73))*3+ (('Group Stage'!$C$2:$C$73=A12)*('Group Stage'!$E$2:$E$73='Group Stage'!$F$2:$F$73))*1+ (('Group Stage'!$D$2:$D$73=A12)*('Group Stage'!$F$2:$F$73='Group Stage'!$E$2:$E$73))*1 )} -> 4 | Q12: {=SUMPRODUCT( ('Group Stage'!$C$2:$C$73=A12)*('Group Stage'!$E$2:$E$73-'Group Stage'!$F$2:$F$73)+ ('Group Stage'!$D$2:$D$73=A12)*('Group Stage'!$F$2:$F$73-'Group Stage'!$E$2:$E$73) )} -> 0 | R12: {=SUMPRODUCT( ('Group Stage'!$C$2:$C$73=A12)*'Group Stage'!$E$2:$E$73+ ('Group Stage'!$D$2:$D$73=A12)*'Group Stage'!$F$2:$F$73 )} -> 2 | S12: {=SUMPRODUCT( (('Elimination Rounds'!$L$2:$L$49=L12)* (('Elimination Rounds'!$P$2:$P$49>P12)+ ('Elimination Rounds'!$P$2:$P$49=P12)*('Elimination Rounds'!$Q$2:$Q$49>Q12)+ ('Elimination Rounds'!$P$2:$P$49=P12)*('Elimination Rounds'!$Q$2:$Q$49=Q12)*('Elimination Rounds'!$R$2:$R$49>R12))) )+1} -> 3 | U12: Scotland | V12: C | W12: 1 | X12: 1 | Y12: 1 | Z12: 4 | AA12: 0 | AB12: 2 | AC12: 3
A13: Haiti | B13: =C13&D13 -> C4 | C13: C | D13: 4 | K13: Haiti | L13: C | M13: {=SUMPRODUCT( (('Group Stage'!$C$2:$C$73=A13)*('Group Stage'!$E$2:$E$73>'Group Stage'!$F$2:$F$73))+ (('Group Stage'!$D$2:$D$73=A13)*('Group Stage'!$F$2:$F$73>'Group Stage'!$E$2:$E$73)) )} -> 0 | N13: {=SUMPRODUCT( (('Group Stage'!$C$2:$C$73=A13)*('Group Stage'!$E$2:$E$73='Group Stage'!$F$2:$F$73))+ (('Group Stage'!$D$2:$D$73=A13)*('Group Stage'!$F$2:$F$73='Group Stage'!$E$2:$E$73)) )} -> 0 | O13: {=SUMPRODUCT( (('Group Stage'!$C$2:$C$73=A13)*('Group Stage'!$E$2:$E$73<'Group Stage'!$F$2:$F$73))+ (('Group Stage'!$D$2:$D$73=A13)*('Group Stage'!$F$2:$F$73<'Group Stage'!$E$2:$E$73)) )} -> 3 | P13: {=SUMPRODUCT( (('Group Stage'!$C$2:$C$73=A13)*('Group Stage'!$E$2:$E$73>'Group Stage'!$F$2:$F$73))*3+ (('Group Stage'!$D$2:$D$73=A13)*('Group Stage'!$F$2:$F$73>'Group Stage'!$E$2:$E$73))*3+ (('Group Stage'!$C$2:$C$73=A13)*('Group Stage'!$E$2:$E$73='Group Stage'!$F$2:$F$73))*1+ (('Group Stage'!$D$2:$D$73=A13)*('Group Stage'!$F$2:$F$73='Group Stage'!$E$2:$E$73))*1 )} -> 0 | Q13: {=SUMPRODUCT( ('Group Stage'!$C$2:$C$73=A13)*('Group Stage'!$E$2:$E$73-'Group Stage'!$F$2:$F$73)+ ('Group Stage'!$D$2:$D$73=A13)*('Group Stage'!$F$2:$F$73-'Group Stage'!$E$2:$E$73) )} -> -6 | R13: {=SUMPRODUCT( ('Group Stage'!$C$2:$C$73=A13)*'Group Stage'!$E$2:$E$73+ ('Group Stage'!$D$2:$D$73=A13)*'Group Stage'!$F$2:$F$73 )} -> 0 | S13: {=SUMPRODUCT( (('Elimination Rounds'!$L$2:$L$49=L13)* (('Elimination Rounds'!$P$2:$P$49>P13)+ ('Elimination Rounds'!$P$2:$P$49=P13)*('Elimination Rounds'!$Q$2:$Q$49>Q13)+ ('Elimination Rounds'!$P$2:$P$49=P13)*('Elimination Rounds'!$Q$2:$Q$49=Q13)*('Elimination Rounds'!$R$2:$R$49>R13))) )+1} -> 4 | U13: Haiti | V13: C | W13: 0 | X13: 0 | Y13: 3 | Z13: 0 | AA13: -6 | AB13: 0 | AC13: 4 | AF13: Team | AG13: Code | AH13: Win | AI13: D | AJ13: L | AK13: Pts | AL13: GD | AM13: GF | AN13: Group Rank | AP13: Team | AQ13: Code | AR13: Win | AS13: D | AT13: L | AU13: Pts | AV13: GD | AW13: GF | AX13: Group Rank
A14: USA | B14: =C14&D14 -> D2 | C14: D | D14: 2 | E14: 1 | K14: USA | L14: D | M14: {=SUMPRODUCT( (('Group Stage'!$C$2:$C$73=A14)*('Group Stage'!$E$2:$E$73>'Group Stage'!$F$2:$F$73))+ (('Group Stage'!$D$2:$D$73=A14)*('Group Stage'!$F$2:$F$73>'Group Stage'!$E$2:$E$73)) )} -> 1 | N14: {=SUMPRODUCT( (('Group Stage'!$C$2:$C$73=A14)*('Group Stage'!$E$2:$E$73='Group Stage'!$F$2:$F$73))+ (('Group Stage'!$D$2:$D$73=A14)*('Group Stage'!$F$2:$F$73='Group Stage'!$E$2:$E$73)) )} -> 2 | O14: {=SUMPRODUCT( (('Group Stage'!$C$2:$C$73=A14)*('Group Stage'!$E$2:$E$73<'Group Stage'!$F$2:$F$73))+ (('Group Stage'!$D$2:$D$73=A14)*('Group Stage'!$F$2:$F$73<'Group Stage'!$E$2:$E$73)) )} -> 0 | P14: {=SUMPRODUCT( (('Group Stage'!$C$2:$C$73=A14)*('Group Stage'!$E$2:$E$73>'Group Stage'!$F$2:$F$73))*3+ (('Group Stage'!$D$2:$D$73=A14)*('Group Stage'!$F$2:$F$73>'Group Stage'!$E$2:$E$73))*3+ (('Group Stage'!$C$2:$C$73=A14)*('Group Stage'!$E$2:$E$73='Group Stage'!$F$2:$F$73))*1+ (('Group Stage'!$D$2:$D$73=A14)*('Group Stage'!$F$2:$F$73='Group Stage'!$E$2:$E$73))*1 )} -> 5 | Q14: {=SUMPRODUCT( ('Group Stage'!$C$2:$C$73=A14)*('Group Stage'!$E$2:$E$73-'Group Stage'!$F$2:$F$73)+ ('Group Stage'!$D$2:$D$73=A14)*('Group Stage'!$F$2:$F$73-'Group Stage'!$E$2:$E$73) )} -> 1 | R14: {=SUMPRODUCT( ('Group Stage'!$C$2:$C$73=A14)*'Group Stage'!$E$2:$E$73+ ('Group Stage'!$D$2:$D$73=A14)*'Group Stage'!$F$2:$F$73 )} -> 2 | S14: {=SUMPRODUCT( (('Elimination Rounds'!$L$2:$L$49=L14)* (('Elimination Rounds'!$P$2:$P$49>P14)+ ('Elimination Rounds'!$P$2:$P$49=P14)*('Elimination Rounds'!$Q$2:$Q$49>Q14)+ ('Elimination Rounds'!$P$2:$P$49=P14)*('Elimination Rounds'!$Q$2:$Q$49=Q14)*('Elimination Rounds'!$R$2:$R$49>R14))) )+1} -> 2 | U14: Turkiye | V14: D | W14: 2 | X14: 1 | Y14: 0 | Z14: 7 | AA14: 2 | AB14: 2 | AC14: 1 | AF14: =U10 -> Brazil | AG14: =V10 -> C | AH14: =W10 -> 3 | AI14: =X10 -> 0 | AJ14: =Y10 -> 0 | AK14: =Z10 -> 9 | AL14: =AA10 -> 5 | AM14: =AB10 -> 5 | AN14: =AC10 -> 1 | AP14: =U42 -> Portugal | AQ14: =V42 -> K | AR14: =W42 -> 3 | AS14: =X42 -> 0 | AT14: =Y42 -> 0 | AU14: =Z42 -> 9 | AV14: =AA42 -> 8 | AW14: =AB42 -> 8 | AX14: =AC42 -> 1
A15: Paraguay | B15: =C15&D15 -> D4 | C15: D | D15: 4 | K15: Paraguay | L15: D | M15: {=SUMPRODUCT( (('Group Stage'!$C$2:$C$73=A15)*('Group Stage'!$E$2:$E$73>'Group Stage'!$F$2:$F$73))+ (('Group Stage'!$D$2:$D$73=A15)*('Group Stage'!$F$2:$F$73>'Group Stage'!$E$2:$E$73)) )} -> 0 | N15: {=SUMPRODUCT( (('Group Stage'!$C$2:$C$73=A15)*('Group Stage'!$E$2:$E$73='Group Stage'!$F$2:$F$73))+ (('Group Stage'!$D$2:$D$73=A15)*('Group Stage'!$F$2:$F$73='Group Stage'!$E$2:$E$73)) )} -> 1 | O15: {=SUMPRODUCT( (('Group Stage'!$C$2:$C$73=A15)*('Group Stage'!$E$2:$E$73<'Group Stage'!$F$2:$F$73))+ (('Group Stage'!$D$2:$D$73=A15)*('Group Stage'!$F$2:$F$73<'Group Stage'!$E$2:$E$73)) )} -> 2 | P15: {=SUMPRODUCT( (('Group Stage'!$C$2:$C$73=A15)*('Group Stage'!$E$2:$E$73>'Group Stage'!$F$2:$F$73))*3+ (('Group Stage'!$D$2:$D$73=A15)*('Group Stage'!$F$2:$F$73>'Group Stage'!$E$2:$E$73))*3+ (('Group Stage'!$C$2:$C$73=A15)*('Group Stage'!$E$2:$E$73='Group Stage'!$F$2:$F$73))*1+ (('Group Stage'!$D$2:$D$73=A15)*('Group Stage'!$F$2:$F$73='Group Stage'!$E$2:$E$73))*1 )} -> 1 | Q15: {=SUMPRODUCT( ('Group Stage'!$C$2:$C$73=A15)*('Group Stage'!$E$2:$E$73-'Group Stage'!$F$2:$F$73)+ ('Group Stage'!$D$2:$D$73=A15)*('Group Stage'!$F$2:$F$73-'Group Stage'!$E$2:$E$73) )} -> -2 | R15: {=SUMPRODUCT( ('Group Stage'!$C$2:$C$73=A15)*'Group Stage'!$E$2:$E$73+ ('Group Stage'!$D$2:$D$73=A15)*'Group Stage'!$F$2:$F$73 )} -> 1 | S15: {=SUMPRODUCT( (('Elimination Rounds'!$L$2:$L$49=L15)* (('Elimination Rounds'!$P$2:$P$49>P15)+ ('Elimination Rounds'!$P$2:$P$49=P15)*('Elimination Rounds'!$Q$2:$Q$49>Q15)+ ('Elimination Rounds'!$P$2:$P$49=P15)*('Elimination Rounds'!$Q$2:$Q$49=Q15)*('Elimination Rounds'!$R$2:$R$49>R15))) )+1} -> 4 | U15: USA | V15: D | W15: 1 | X15: 2 | Y15: 0 | Z15: 5 | AA15: 1 | AB15: 2 | AC15: 2 | AF15: =U11 -> Morocco | AG15: =V11 -> C | AH15: =W11 -> 1 | AI15: =X11 -> 1 | AJ15: =Y11 -> 1 | AK15: =Z11 -> 4 | AL15: =AA11 -> 1 | AM15: =AB11 -> 3 | AN15: =AC11 -> 2 | AP15: =U43 -> Colombia | AQ15: =V43 -> K | AR15: =W43 -> 2 | AS15: =X43 -> 0 | AT15: =Y43 -> 1 | AU15: =Z43 -> 6 | AV15: =AA43 -> 2 | AW15: =AB43 -> 4 | AX15: =AC43 -> 2
A16: Australia | B16: =C16&D16 -> D3 | C16: D | D16: 3 | K16: Australia | L16: D | M16: {=SUMPRODUCT( (('Group Stage'!$C$2:$C$73=A16)*('Group Stage'!$E$2:$E$73>'Group Stage'!$F$2:$F$73))+ (('Group Stage'!$D$2:$D$73=A16)*('Group Stage'!$F$2:$F$73>'Group Stage'!$E$2:$E$73)) )} -> 0 | N16: {=SUMPRODUCT( (('Group Stage'!$C$2:$C$73=A16)*('Group Stage'!$E$2:$E$73='Group Stage'!$F$2:$F$73))+ (('Group Stage'!$D$2:$D$73=A16)*('Group Stage'!$F$2:$F$73='Group Stage'!$E$2:$E$73)) )} -> 2 | O16: {=SUMPRODUCT( (('Group Stage'!$C$2:$C$73=A16)*('Group Stage'!$E$2:$E$73<'Group Stage'!$F$2:$F$73))+ (('Group Stage'!$D$2:$D$73=A16)*('Group Stage'!$F$2:$F$73<'Group Stage'!$E$2:$E$73)) )} -> 1 | P16: {=SUMPRODUCT( (('Group Stage'!$C$2:$C$73=A16)*('Group Stage'!$E$2:$E$73>'Group Stage'!$F$2:$F$73))*3+ (('Group Stage'!$D$2:$D$73=A16)*('Group Stage'!$F$2:$F$73>'Group Stage'!$E$2:$E$73))*3+ (('Group Stage'!$C$2:$C$73=A16)*('Group Stage'!$E$2:$E$73='Group Stage'!$F$2:$F$73))*1+ (('Group Stage'!$D$2:$D$73=A16)*('Group Stage'!$F$2:$F$73='Group Stage'!$E$2:$E$73))*1 )} -> 2 | Q16: {=SUMPRODUCT( ('Group Stage'!$C$2:$C$73=A16)*('Group Stage'!$E$2:$E$73-'Group Stage'!$F$2:$F$73)+ ('Group Stage'!$D$2:$D$73=A16)*('Group Stage'!$F$2:$F$73-'Group Stage'!$E$2:$E$73) )} -> -1 | R16: {=SUMPRODUCT( ('Group Stage'!$C$2:$C$73=A16)*'Group Stage'!$E$2:$E$73+ ('Group Stage'!$D$2:$D$73=A16)*'Group Stage'!$F$2:$F$73 )} -> 2 | S16: {=SUMPRODUCT( (('Elimination Rounds'!$L$2:$L$49=L16)* (('Elimination Rounds'!$P$2:$P$49>P16)+ ('Elimination Rounds'!$P$2:$P$49=P16)*('Elimination Rounds'!$Q$2:$Q$49>Q16)+ ('Elimination Rounds'!$P$2:$P$49=P16)*('Elimination Rounds'!$Q$2:$Q$49=Q16)*('Elimination Rounds'!$R$2:$R$49>R16))) )+1} -> 3 | U16: Australia | V16: D | W16: 0 | X16: 2 | Y16: 1 | Z16: 2 | AA16: -1 | AB16: 2 | AC16: 3 | AF16: =U12 -> Scotland | AG16: =V12 -> C | AH16: =W12 -> 1 | AI16: =X12 -> 1 | AJ16: =Y12 -> 1 | AK16: =Z12 -> 4 | AL16: =AA12 -> 0 | AM16: =AB12 -> 2 | AN16: =AC12 -> 3 | AP16: =U44 -> DR Congo | AQ16: =V44 -> K | AR16: =W44 -> 0 | AS16: =X44 -> 1 | AT16: =Y44 -> 2 | AU16: =Z44 -> 1 | AV16: =AA44 -> -4 | AW16: =AB44 -> 0 | AX16: =AC44 -> 3
A17: Turkiye | B17: =C17&D17 -> D1 | C17: D | D17: 1 | E17: 1 | K17: Turkiye | L17: D | M17: {=SUMPRODUCT( (('Group Stage'!$C$2:$C$73=A17)*('Group Stage'!$E$2:$E$73>'Group Stage'!$F$2:$F$73))+ (('Group Stage'!$D$2:$D$73=A17)*('Group Stage'!$F$2:$F$73>'Group Stage'!$E$2:$E$73)) )} -> 2 | N17: {=SUMPRODUCT( (('Group Stage'!$C$2:$C$73=A17)*('Group Stage'!$E$2:$E$73='Group Stage'!$F$2:$F$73))+ (('Group Stage'!$D$2:$D$73=A17)*('Group Stage'!$F$2:$F$73='Group Stage'!$E$2:$E$73)) )} -> 1 | O17: {=SUMPRODUCT( (('Group Stage'!$C$2:$C$73=A17)*('Group Stage'!$E$2:$E$73<'Group Stage'!$F$2:$F$73))+ (('Group Stage'!$D$2:$D$73=A17)*('Group Stage'!$F$2:$F$73<'Group Stage'!$E$2:$E$73)) )} -> 0 | P17: {=SUMPRODUCT( (('Group Stage'!$C$2:$C$73=A17)*('Group Stage'!$E$2:$E$73>'Group Stage'!$F$2:$F$73))*3+ (('Group Stage'!$D$2:$D$73=A17)*('Group Stage'!$F$2:$F$73>'Group Stage'!$E$2:$E$73))*3+ (('Group Stage'!$C$2:$C$73=A17)*('Group Stage'!$E$2:$E$73='Group Stage'!$F$2:$F$73))*1+ (('Group Stage'!$D$2:$D$73=A17)*('Group Stage'!$F$2:$F$73='Group Stage'!$E$2:$E$73))*1 )} -> 7 | Q17: {=SUMPRODUCT( ('Group Stage'!$C$2:$C$73=A17)*('Group Stage'!$E$2:$E$73-'Group Stage'!$F$2:$F$73)+ ('Group Stage'!$D$2:$D$73=A17)*('Group Stage'!$F$2:$F$73-'Group Stage'!$E$2:$E$73) )} -> 2 | R17: {=SUMPRODUCT( ('Group Stage'!$C$2:$C$73=A17)*'Group Stage'!$E$2:$E$73+ ('Group Stage'!$D$2:$D$73=A17)*'Group Stage'!$F$2:$F$73 )} -> 2 | S17: {=SUMPRODUCT( (('Elimination Rounds'!$L$2:$L$49=L17)* (('Elimination Rounds'!$P$2:$P$49>P17)+ ('Elimination Rounds'!$P$2:$P$49=P17)*('Elimination Rounds'!$Q$2:$Q$49>Q17)+ ('Elimination Rounds'!$P$2:$P$49=P17)*('Elimination Rounds'!$Q$2:$Q$49=Q17)*('Elimination Rounds'!$R$2:$R$49>R17))) )+1} -> 1 | U17: Paraguay | V17: D | W17: 0 | X17: 1 | Y17: 2 | Z17: 1 | AA17: -2 | AB17: 1 | AC17: 4 | AF17: =U13 -> Haiti | AG17: =V13 -> C | AH17: =W13 -> 0 | AI17: =X13 -> 0 | AJ17: =Y13 -> 3 | AK17: =Z13 -> 0 | AL17: =AA13 -> -6 | AM17: =AB13 -> 0 | AN17: =AC13 -> 4 | AP17: =U45 -> Uzbekistan | AQ17: =V45 -> K | AR17: =W45 -> 0 | AS17: =X45 -> 1 | AT17: =Y45 -> 2 | AU17: =Z45 -> 1 | AV17: =AA45 -> -6 | AW17: =AB45 -> 0 | AX17: =AC45 -> 4
A18: Germany | B18: =C18&D18 -> E1 | C18: E | D18: 1 | E18: 1 | K18: Germany | L18: E | M18: {=SUMPRODUCT( (('Group Stage'!$C$2:$C$73=A18)*('Group Stage'!$E$2:$E$73>'Group Stage'!$F$2:$F$73))+ (('Group Stage'!$D$2:$D$73=A18)*('Group Stage'!$F$2:$F$73>'Group Stage'!$E$2:$E$73)) )} -> 3 | N18: {=SUMPRODUCT( (('Group Stage'!$C$2:$C$73=A18)*('Group Stage'!$E$2:$E$73='Group Stage'!$F$2:$F$73))+ (('Group Stage'!$D$2:$D$73=A18)*('Group Stage'!$F$2:$F$73='Group Stage'!$E$2:$E$73)) )} -> 0 | O18: {=SUMPRODUCT( (('Group Stage'!$C$2:$C$73=A18)*('Group Stage'!$E$2:$E$73<'Group Stage'!$F$2:$F$73))+ (('Group Stage'!$D$2:$D$73=A18)*('Group Stage'!$F$2:$F$73<'Group Stage'!$E$2:$E$73)) )} -> 0 | P18: {=SUMPRODUCT( (('Group Stage'!$C$2:$C$73=A18)*('Group Stage'!$E$2:$E$73>'Group Stage'!$F$2:$F$73))*3+ (('Group Stage'!$D$2:$D$73=A18)*('Group Stage'!$F$2:$F$73>'Group Stage'!$E$2:$E$73))*3+ (('Group Stage'!$C$2:$C$73=A18)*('Group Stage'!$E$2:$E$73='Group Stage'!$F$2:$F$73))*1+ (('Group Stage'!$D$2:$D$73=A18)*('Group Stage'!$F$2:$F$73='Group Stage'!$E$2:$E$73))*1 )} -> 9 | Q18: {=SUMPRODUCT( ('Group Stage'!$C$2:$C$73=A18)*('Group Stage'!$E$2:$E$73-'Group Stage'!$F$2:$F$73)+ ('Group Stage'!$D$2:$D$73=A18)*('Group Stage'!$F$2:$F$73-'Group Stage'!$E$2:$E$73) )} -> 5 | R18: {=SUMPRODUCT( ('Group Stage'!$C$2:$C$73=A18)*'Group Stage'!$E$2:$E$73+ ('Group Stage'!$D$2:$D$73=A18)*'Group Stage'!$F$2:$F$73 )} -> 5 | S18: {=SUMPRODUCT( (('Elimination Rounds'!$L$2:$L$49=L18)* (('Elimination Rounds'!$P$2:$P$49>P18)+ ('Elimination Rounds'!$P$2:$P$49=P18)*('Elimination Rounds'!$Q$2:$Q$49>Q18)+ ('Elimination Rounds'!$P$2:$P$49=P18)*('Elimination Rounds'!$Q$2:$Q$49=Q18)*('Elimination Rounds'!$R$2:$R$49>R18))) )+1} -> 1 | U18: Germany | V18: E | W18: 3 | X18: 0 | Y18: 0 | Z18: 9 | AA18: 5 | AB18: 5 | AC18: 1
A19: Ecuador | B19: =C19&D19 -> E2 | C19: E | D19: 2 | K19: Ecuador | L19: E | M19: {=SUMPRODUCT( (('Group Stage'!$C$2:$C$73=A19)*('Group Stage'!$E$2:$E$73>'Group Stage'!$F$2:$F$73))+ (('Group Stage'!$D$2:$D$73=A19)*('Group Stage'!$F$2:$F$73>'Group Stage'!$E$2:$E$73)) )} -> 1 | N19: {=SUMPRODUCT( (('Group Stage'!$C$2:$C$73=A19)*('Group Stage'!$E$2:$E$73='Group Stage'!$F$2:$F$73))+ (('Group Stage'!$D$2:$D$73=A19)*('Group Stage'!$F$2:$F$73='Group Stage'!$E$2:$E$73)) )} -> 1 | O19: {=SUMPRODUCT( (('Group Stage'!$C$2:$C$73=A19)*('Group Stage'!$E$2:$E$73<'Group Stage'!$F$2:$F$73))+ (('Group Stage'!$D$2:$D$73=A19)*('Group Stage'!$F$2:$F$73<'Group Stage'!$E$2:$E$73)) )} -> 1 | P19: {=SUMPRODUCT( (('Group Stage'!$C$2:$C$73=A19)*('Group Stage'!$E$2:$E$73>'Group Stage'!$F$2:$F$73))*3+ (('Group Stage'!$D$2:$D$73=A19)*('Group Stage'!$F$2:$F$73>'Group Stage'!$E$2:$E$73))*3+ (('Group Stage'!$C$2:$C$73=A19)*('Group Stage'!$E$2:$E$73='Group Stage'!$F$2:$F$73))*1+ (('Group Stage'!$D$2:$D$73=A19)*('Group Stage'!$F$2:$F$73='Group Stage'!$E$2:$E$73))*1 )} -> 4 | Q19: {=SUMPRODUCT( ('Group Stage'!$C$2:$C$73=A19)*('Group Stage'!$E$2:$E$73-'Group Stage'!$F$2:$F$73)+ ('Group Stage'!$D$2:$D$73=A19)*('Group Stage'!$F$2:$F$73-'Group Stage'!$E$2:$E$73) )} -> 1 | R19: {=SUMPRODUCT( ('Group Stage'!$C$2:$C$73=A19)*'Group Stage'!$E$2:$E$73+ ('Group Stage'!$D$2:$D$73=A19)*'Group Stage'!$F$2:$F$73 )} -> 3 | S19: {=SUMPRODUCT( (('Elimination Rounds'!$L$2:$L$49=L19)* (('Elimination Rounds'!$P$2:$P$49>P19)+ ('Elimination Rounds'!$P$2:$P$49=P19)*('Elimination Rounds'!$Q$2:$Q$49>Q19)+ ('Elimination Rounds'!$P$2:$P$49=P19)*('Elimination Rounds'!$Q$2:$Q$49=Q19)*('Elimination Rounds'!$R$2:$R$49>R19))) )+1} -> 2 | U19: Ecuador | V19: E | W19: 1 | X19: 1 | Y19: 1 | Z19: 4 | AA19: 1 | AB19: 3 | AC19: 2 | AF19: Team | AG19: Code | AH19: Win | AI19: D | AJ19: L | AK19: Pts | AL19: GD | AM19: GF | AN19: Group Rank | AP19: Team | AQ19: Code | AR19: Win | AS19: D | AT19: L | AU19: Pts | AV19: GD | AW19: GF | AX19: Group Rank
A20: Ivory Coast | B20: =C20&D20 -> E3 | C20: E | D20: 3 | E20: 1 | K20: Ivory Coast | L20: E | M20: {=SUMPRODUCT( (('Group Stage'!$C$2:$C$73=A20)*('Group Stage'!$E$2:$E$73>'Group Stage'!$F$2:$F$73))+ (('Group Stage'!$D$2:$D$73=A20)*('Group Stage'!$F$2:$F$73>'Group Stage'!$E$2:$E$73)) )} -> 1 | N20: {=SUMPRODUCT( (('Group Stage'!$C$2:$C$73=A20)*('Group Stage'!$E$2:$E$73='Group Stage'!$F$2:$F$73))+ (('Group Stage'!$D$2:$D$73=A20)*('Group Stage'!$F$2:$F$73='Group Stage'!$E$2:$E$73)) )} -> 1 | O20: {=SUMPRODUCT( (('Group Stage'!$C$2:$C$73=A20)*('Group Stage'!$E$2:$E$73<'Group Stage'!$F$2:$F$73))+ (('Group Stage'!$D$2:$D$73=A20)*('Group Stage'!$F$2:$F$73<'Group Stage'!$E$2:$E$73)) )} -> 1 | P20: {=SUMPRODUCT( (('Group Stage'!$C$2:$C$73=A20)*('Group Stage'!$E$2:$E$73>'Group Stage'!$F$2:$F$73))*3+ (('Group Stage'!$D$2:$D$73=A20)*('Group Stage'!$F$2:$F$73>'Group Stage'!$E$2:$E$73))*3+ (('Group Stage'!$C$2:$C$73=A20)*('Group Stage'!$E$2:$E$73='Group Stage'!$F$2:$F$73))*1+ (('Group Stage'!$D$2:$D$73=A20)*('Group Stage'!$F$2:$F$73='Group Stage'!$E$2:$E$73))*1 )} -> 4 | Q20: {=SUMPRODUCT( ('Group Stage'!$C$2:$C$73=A20)*('Group Stage'!$E$2:$E$73-'Group Stage'!$F$2:$F$73)+ ('Group Stage'!$D$2:$D$73=A20)*('Group Stage'!$F$2:$F$73-'Group Stage'!$E$2:$E$73) )} -> 0 | R20: {=SUMPRODUCT( ('Group Stage'!$C$2:$C$73=A20)*'Group Stage'!$E$2:$E$73+ ('Group Stage'!$D$2:$D$73=A20)*'Group Stage'!$F$2:$F$73 )} -> 3 | S20: {=SUMPRODUCT( (('Elimination Rounds'!$L$2:$L$49=L20)* (('Elimination Rounds'!$P$2:$P$49>P20)+ ('Elimination Rounds'!$P$2:$P$49=P20)*('Elimination Rounds'!$Q$2:$Q$49>Q20)+ ('Elimination Rounds'!$P$2:$P$49=P20)*('Elimination Rounds'!$Q$2:$Q$49=Q20)*('Elimination Rounds'!$R$2:$R$49>R20))) )+1} -> 3 | U20: Ivory Coast | V20: E | W20: 1 | X20: 1 | Y20: 1 | Z20: 4 | AA20: 0 | AB20: 3 | AC20: 3 | AF20: =U14 -> Turkiye | AG20: =V14 -> D | AH20: =W14 -> 2 | AI20: =X14 -> 1 | AJ20: =Y14 -> 0 | AK20: =Z14 -> 7 | AL20: =AA14 -> 2 | AM20: =AB14 -> 2 | AN20: =AC14 -> 1 | AP20: =U46 -> England | AQ20: =V46 -> L | AR20: =W46 -> 3 | AS20: =X46 -> 0 | AT20: =Y46 -> 0 | AU20: =Z46 -> 9 | AV20: =AA46 -> 4 | AW20: =AB46 -> 5 | AX20: =AC46 -> 1
A21: Curacao | B21: =C21&D21 -> E4 | C21: E | D21: 4 | K21: Curacao | L21: E | M21: {=SUMPRODUCT( (('Group Stage'!$C$2:$C$73=A21)*('Group Stage'!$E$2:$E$73>'Group Stage'!$F$2:$F$73))+ (('Group Stage'!$D$2:$D$73=A21)*('Group Stage'!$F$2:$F$73>'Group Stage'!$E$2:$E$73)) )} -> 0 | N21: {=SUMPRODUCT( (('Group Stage'!$C$2:$C$73=A21)*('Group Stage'!$E$2:$E$73='Group Stage'!$F$2:$F$73))+ (('Group Stage'!$D$2:$D$73=A21)*('Group Stage'!$F$2:$F$73='Group Stage'!$E$2:$E$73)) )} -> 0 | O21: {=SUMPRODUCT( (('Group Stage'!$C$2:$C$73=A21)*('Group Stage'!$E$2:$E$73<'Group Stage'!$F$2:$F$73))+ (('Group Stage'!$D$2:$D$73=A21)*('Group Stage'!$F$2:$F$73<'Group Stage'!$E$2:$E$73)) )} -> 3 | P21: {=SUMPRODUCT( (('Group Stage'!$C$2:$C$73=A21)*('Group Stage'!$E$2:$E$73>'Group Stage'!$F$2:$F$73))*3+ (('Group Stage'!$D$2:$D$73=A21)*('Group Stage'!$F$2:$F$73>'Group Stage'!$E$2:$E$73))*3+ (('Group Stage'!$C$2:$C$73=A21)*('Group Stage'!$E$2:$E$73='Group Stage'!$F$2:$F$73))*1+ (('Group Stage'!$D$2:$D$73=A21)*('Group Stage'!$F$2:$F$73='Group Stage'!$E$2:$E$73))*1 )} -> 0 | Q21: {=SUMPRODUCT( ('Group Stage'!$C$2:$C$73=A21)*('Group Stage'!$E$2:$E$73-'Group Stage'!$F$2:$F$73)+ ('Group Stage'!$D$2:$D$73=A21)*('Group Stage'!$F$2:$F$73-'Group Stage'!$E$2:$E$73) )} -> -6 | R21: {=SUMPRODUCT( ('Group Stage'!$C$2:$C$73=A21)*'Group Stage'!$E$2:$E$73+ ('Group Stage'!$D$2:$D$73=A21)*'Group Stage'!$F$2:$F$73 )} -> 0 | S21: {=SUMPRODUCT( (('Elimination Rounds'!$L$2:$L$49=L21)* (('Elimination Rounds'!$P$2:$P$49>P21)+ ('Elimination Rounds'!$P$2:$P$49=P21)*('Elimination Rounds'!$Q$2:$Q$49>Q21)+ ('Elimination Rounds'!$P$2:$P$49=P21)*('Elimination Rounds'!$Q$2:$Q$49=Q21)*('Elimination Rounds'!$R$2:$R$49>R21))) )+1} -> 4 | U21: Curacao | V21: E | W21: 0 | X21: 0 | Y21: 3 | Z21: 0 | AA21: -6 | AB21: 0 | AC21: 4 | AF21: =U15 -> USA | AG21: =V15 -> D | AH21: =W15 -> 1 | AI21: =X15 -> 2 | AJ21: =Y15 -> 0 | AK21: =Z15 -> 5 | AL21: =AA15 -> 1 | AM21: =AB15 -> 2 | AN21: =AC15 -> 2 | AP21: =U47 -> Croatia | AQ21: =V47 -> L | AR21: =W47 -> 1 | AS21: =X47 -> 1 | AT21: =Y47 -> 1 | AU21: =Z47 -> 4 | AV21: =AA47 -> 1 | AW21: =AB47 -> 4 | AX21: =AC47 -> 2
A22: Netherlands | B22: =C22&D22 -> F1 | C22: F | D22: 1 | E22: 1 | F22: 1 | K22: Netherlands | L22: F | M22: {=SUMPRODUCT( (('Group Stage'!$C$2:$C$73=A22)*('Group Stage'!$E$2:$E$73>'Group Stage'!$F$2:$F$73))+ (('Group Stage'!$D$2:$D$73=A22)*('Group Stage'!$F$2:$F$73>'Group Stage'!$E$2:$E$73)) )} -> 3 | N22: {=SUMPRODUCT( (('Group Stage'!$C$2:$C$73=A22)*('Group Stage'!$E$2:$E$73='Group Stage'!$F$2:$F$73))+ (('Group Stage'!$D$2:$D$73=A22)*('Group Stage'!$F$2:$F$73='Group Stage'!$E$2:$E$73)) )} -> 0 | O22: {=SUMPRODUCT( (('Group Stage'!$C$2:$C$73=A22)*('Group Stage'!$E$2:$E$73<'Group Stage'!$F$2:$F$73))+ (('Group Stage'!$D$2:$D$73=A22)*('Group Stage'!$F$2:$F$73<'Group Stage'!$E$2:$E$73)) )} -> 0 | P22: {=SUMPRODUCT( (('Group Stage'!$C$2:$C$73=A22)*('Group Stage'!$E$2:$E$73>'Group Stage'!$F$2:$F$73))*3+ (('Group Stage'!$D$2:$D$73=A22)*('Group Stage'!$F$2:$F$73>'Group Stage'!$E$2:$E$73))*3+ (('Group Stage'!$C$2:$C$73=A22)*('Group Stage'!$E$2:$E$73='Group Stage'!$F$2:$F$73))*1+ (('Group Stage'!$D$2:$D$73=A22)*('Group Stage'!$F$2:$F$73='Group Stage'!$E$2:$E$73))*1 )} -> 9 | Q22: {=SUMPRODUCT( ('Group Stage'!$C$2:$C$73=A22)*('Group Stage'!$E$2:$E$73-'Group Stage'!$F$2:$F$73)+ ('Group Stage'!$D$2:$D$73=A22)*('Group Stage'!$F$2:$F$73-'Group Stage'!$E$2:$E$73) )} -> 4 | R22: {=SUMPRODUCT( ('Group Stage'!$C$2:$C$73=A22)*'Group Stage'!$E$2:$E$73+ ('Group Stage'!$D$2:$D$73=A22)*'Group Stage'!$F$2:$F$73 )} -> 4 | S22: {=SUMPRODUCT( (('Elimination Rounds'!$L$2:$L$49=L22)* (('Elimination Rounds'!$P$2:$P$49>P22)+ ('Elimination Rounds'!$P$2:$P$49=P22)*('Elimination Rounds'!$Q$2:$Q$49>Q22)+ ('Elimination Rounds'!$P$2:$P$49=P22)*('Elimination Rounds'!$Q$2:$Q$49=Q22)*('Elimination Rounds'!$R$2:$R$49>R22))) )+1} -> 1 | U22: Netherlands | V22: F | W22: 3 | X22: 0 | Y22: 0 | Z22: 9 | AA22: 4 | AB22: 4 | AC22: 1 | AF22: =U16 -> Australia | AG22: =V16 -> D | AH22: =W16 -> 0 | AI22: =X16 -> 2 | AJ22: =Y16 -> 1 | AK22: =Z16 -> 2 | AL22: =AA16 -> -1 | AM22: =AB16 -> 2 | AN22: =AC16 -> 3 | AP22: =U48 -> Ghana | AQ22: =V48 -> L | AR22: =W48 -> 1 | AS22: =X48 -> 1 | AT22: =Y48 -> 1 | AU22: =Z48 -> 4 | AV22: =AA48 -> 0 | AW22: =AB48 -> 2 | AX22: =AC48 -> 3
A23: Japan | B23: =C23&D23 -> F2 | C23: F | D23: 2 | K23: Japan | L23: F | M23: {=SUMPRODUCT( (('Group Stage'!$C$2:$C$73=A23)*('Group Stage'!$E$2:$E$73>'Group Stage'!$F$2:$F$73))+ (('Group Stage'!$D$2:$D$73=A23)*('Group Stage'!$F$2:$F$73>'Group Stage'!$E$2:$E$73)) )} -> 1 | N23: {=SUMPRODUCT( (('Group Stage'!$C$2:$C$73=A23)*('Group Stage'!$E$2:$E$73='Group Stage'!$F$2:$F$73))+ (('Group Stage'!$D$2:$D$73=A23)*('Group Stage'!$F$2:$F$73='Group Stage'!$E$2:$E$73)) )} -> 1 | O23: {=SUMPRODUCT( (('Group Stage'!$C$2:$C$73=A23)*('Group Stage'!$E$2:$E$73<'Group Stage'!$F$2:$F$73))+ (('Group Stage'!$D$2:$D$73=A23)*('Group Stage'!$F$2:$F$73<'Group Stage'!$E$2:$E$73)) )} -> 1 | P23: {=SUMPRODUCT( (('Group Stage'!$C$2:$C$73=A23)*('Group Stage'!$E$2:$E$73>'Group Stage'!$F$2:$F$73))*3+ (('Group Stage'!$D$2:$D$73=A23)*('Group Stage'!$F$2:$F$73>'Group Stage'!$E$2:$E$73))*3+ (('Group Stage'!$C$2:$C$73=A23)*('Group Stage'!$E$2:$E$73='Group Stage'!$F$2:$F$73))*1+ (('Group Stage'!$D$2:$D$73=A23)*('Group Stage'!$F$2:$F$73='Group Stage'!$E$2:$E$73))*1 )} -> 4 | Q23: {=SUMPRODUCT( ('Group Stage'!$C$2:$C$73=A23)*('Group Stage'!$E$2:$E$73-'Group Stage'!$F$2:$F$73)+ ('Group Stage'!$D$2:$D$73=A23)*('Group Stage'!$F$2:$F$73-'Group Stage'!$E$2:$E$73) )} -> 1 | R23: {=SUMPRODUCT( ('Group Stage'!$C$2:$C$73=A23)*'Group Stage'!$E$2:$E$73+ ('Group Stage'!$D$2:$D$73=A23)*'Group Stage'!$F$2:$F$73 )} -> 3 | S23: {=SUMPRODUCT( (('Elimination Rounds'!$L$2:$L$49=L23)* (('Elimination Rounds'!$P$2:$P$49>P23)+ ('Elimination Rounds'!$P$2:$P$49=P23)*('Elimination Rounds'!$Q$2:$Q$49>Q23)+ ('Elimination Rounds'!$P$2:$P$49=P23)*('Elimination Rounds'!$Q$2:$Q$49=Q23)*('Elimination Rounds'!$R$2:$R$49>R23))) )+1} -> 2 | U23: Japan | V23: F | W23: 1 | X23: 1 | Y23: 1 | Z23: 4 | AA23: 1 | AB23: 3 | AC23: 2 | AF23: =U17 -> Paraguay | AG23: =V17 -> D | AH23: =W17 -> 0 | AI23: =X17 -> 1 | AJ23: =Y17 -> 2 | AK23: =Z17 -> 1 | AL23: =AA17 -> -2 | AM23: =AB17 -> 1 | AN23: =AC17 -> 4 | AP23: =U49 -> Panama | AQ23: =V49 -> L | AR23: =W49 -> 0 | AS23: =X49 -> 0 | AT23: =Y49 -> 3 | AU23: =Z49 -> 0 | AV23: =AA49 -> -5 | AW23: =AB49 -> 0 | AX23: =AC49 -> 4
A24: Tunisia | B24: =C24&D24 -> F4 | C24: F | D24: 4 | K24: Tunisia | L24: F | M24: {=SUMPRODUCT( (('Group Stage'!$C$2:$C$73=A24)*('Group Stage'!$E$2:$E$73>'Group Stage'!$F$2:$F$73))+ (('Group Stage'!$D$2:$D$73=A24)*('Group Stage'!$F$2:$F$73>'Group Stage'!$E$2:$E$73)) )} -> 0 | N24: {=SUMPRODUCT( (('Group Stage'!$C$2:$C$73=A24)*('Group Stage'!$E$2:$E$73='Group Stage'!$F$2:$F$73))+ (('Group Stage'!$D$2:$D$73=A24)*('Group Stage'!$F$2:$F$73='Group Stage'!$E$2:$E$73)) )} -> 0 | O24: {=SUMPRODUCT( (('Group Stage'!$C$2:$C$73=A24)*('Group Stage'!$E$2:$E$73<'Group Stage'!$F$2:$F$73))+ (('Group Stage'!$D$2:$D$73=A24)*('Group Stage'!$F$2:$F$73<'Group Stage'!$E$2:$E$73)) )} -> 3 | P24: {=SUMPRODUCT( (('Group Stage'!$C$2:$C$73=A24)*('Group Stage'!$E$2:$E$73>'Group Stage'!$F$2:$F$73))*3+ (('Group Stage'!$D$2:$D$73=A24)*('Group Stage'!$F$2:$F$73>'Group Stage'!$E$2:$E$73))*3+ (('Group Stage'!$C$2:$C$73=A24)*('Group Stage'!$E$2:$E$73='Group Stage'!$F$2:$F$73))*1+ (('Group Stage'!$D$2:$D$73=A24)*('Group Stage'!$F$2:$F$73='Group Stage'!$E$2:$E$73))*1 )} -> 0 | Q24: {=SUMPRODUCT( ('Group Stage'!$C$2:$C$73=A24)*('Group Stage'!$E$2:$E$73-'Group Stage'!$F$2:$F$73)+ ('Group Stage'!$D$2:$D$73=A24)*('Group Stage'!$F$2:$F$73-'Group Stage'!$E$2:$E$73) )} -> -5 | R24: {=SUMPRODUCT( ('Group Stage'!$C$2:$C$73=A24)*'Group Stage'!$E$2:$E$73+ ('Group Stage'!$D$2:$D$73=A24)*'Group Stage'!$F$2:$F$73 )} -> 0 | S24: {=SUMPRODUCT( (('Elimination Rounds'!$L$2:$L$49=L24)* (('Elimination Rounds'!$P$2:$P$49>P24)+ ('Elimination Rounds'!$P$2:$P$49=P24)*('Elimination Rounds'!$Q$2:$Q$49>Q24)+ ('Elimination Rounds'!$P$2:$P$49=P24)*('Elimination Rounds'!$Q$2:$Q$49=Q24)*('Elimination Rounds'!$R$2:$R$49>R24))) )+1} -> 4 | U24: Sweden | V24: F | W24: 1 | X24: 1 | Y24: 1 | Z24: 4 | AA24: 0 | AB24: 2 | AC24: 3
A25: Sweden | B25: =C25&D25 -> F3 | C25: F | D25: 3 | K25: Sweden | L25: F | M25: {=SUMPRODUCT( (('Group Stage'!$C$2:$C$73=A25)*('Group Stage'!$E$2:$E$73>'Group Stage'!$F$2:$F$73))+ (('Group Stage'!$D$2:$D$73=A25)*('Group Stage'!$F$2:$F$73>'Group Stage'!$E$2:$E$73)) )} -> 1 | N25: {=SUMPRODUCT( (('Group Stage'!$C$2:$C$73=A25)*('Group Stage'!$E$2:$E$73='Group Stage'!$F$2:$F$73))+ (('Group Stage'!$D$2:$D$73=A25)*('Group Stage'!$F$2:$F$73='Group Stage'!$E$2:$E$73)) )} -> 1 | O25: {=SUMPRODUCT( (('Group Stage'!$C$2:$C$73=A25)*('Group Stage'!$E$2:$E$73<'Group Stage'!$F$2:$F$73))+ (('Group Stage'!$D$2:$D$73=A25)*('Group Stage'!$F$2:$F$73<'Group Stage'!$E$2:$E$73)) )} -> 1 | P25: {=SUMPRODUCT( (('Group Stage'!$C$2:$C$73=A25)*('Group Stage'!$E$2:$E$73>'Group Stage'!$F$2:$F$73))*3+ (('Group Stage'!$D$2:$D$73=A25)*('Group Stage'!$F$2:$F$73>'Group Stage'!$E$2:$E$73))*3+ (('Group Stage'!$C$2:$C$73=A25)*('Group Stage'!$E$2:$E$73='Group Stage'!$F$2:$F$73))*1+ (('Group Stage'!$D$2:$D$73=A25)*('Group Stage'!$F$2:$F$73='Group Stage'!$E$2:$E$73))*1 )} -> 4 | Q25: {=SUMPRODUCT( ('Group Stage'!$C$2:$C$73=A25)*('Group Stage'!$E$2:$E$73-'Group Stage'!$F$2:$F$73)+ ('Group Stage'!$D$2:$D$73=A25)*('Group Stage'!$F$2:$F$73-'Group Stage'!$E$2:$E$73) )} -> 0 | R25: {=SUMPRODUCT( ('Group Stage'!$C$2:$C$73=A25)*'Group Stage'!$E$2:$E$73+ ('Group Stage'!$D$2:$D$73=A25)*'Group Stage'!$F$2:$F$73 )} -> 2 | S25: {=SUMPRODUCT( (('Elimination Rounds'!$L$2:$L$49=L25)* (('Elimination Rounds'!$P$2:$P$49>P25)+ ('Elimination Rounds'!$P$2:$P$49=P25)*('Elimination Rounds'!$Q$2:$Q$49>Q25)+ ('Elimination Rounds'!$P$2:$P$49=P25)*('Elimination Rounds'!$Q$2:$Q$49=Q25)*('Elimination Rounds'!$R$2:$R$49>R25))) )+1} -> 3 | U25: Tunisia | V25: F | W25: 0 | X25: 0 | Y25: 3 | Z25: 0 | AA25: -5 | AB25: 0 | AC25: 4 | AF25: Team | AG25: Code | AH25: Win | AI25: D | AJ25: L | AK25: Pts | AL25: GD | AM25: GF | AN25: Group Rank
A26: Belgium | B26: =C26&D26 -> G1 | C26: G | D26: 1 | E26: 1 | F26: 1 | K26: Belgium | L26: G | M26: {=SUMPRODUCT( (('Group Stage'!$C$2:$C$73=A26)*('Group Stage'!$E$2:$E$73>'Group Stage'!$F$2:$F$73))+ (('Group Stage'!$D$2:$D$73=A26)*('Group Stage'!$F$2:$F$73>'Group Stage'!$E$2:$E$73)) )} -> 3 | N26: {=SUMPRODUCT( (('Group Stage'!$C$2:$C$73=A26)*('Group Stage'!$E$2:$E$73='Group Stage'!$F$2:$F$73))+ (('Group Stage'!$D$2:$D$73=A26)*('Group Stage'!$F$2:$F$73='Group Stage'!$E$2:$E$73)) )} -> 0 | O26: {=SUMPRODUCT( (('Group Stage'!$C$2:$C$73=A26)*('Group Stage'!$E$2:$E$73<'Group Stage'!$F$2:$F$73))+ (('Group Stage'!$D$2:$D$73=A26)*('Group Stage'!$F$2:$F$73<'Group Stage'!$E$2:$E$73)) )} -> 0 | P26: {=SUMPRODUCT( (('Group Stage'!$C$2:$C$73=A26)*('Group Stage'!$E$2:$E$73>'Group Stage'!$F$2:$F$73))*3+ (('Group Stage'!$D$2:$D$73=A26)*('Group Stage'!$F$2:$F$73>'Group Stage'!$E$2:$E$73))*3+ (('Group Stage'!$C$2:$C$73=A26)*('Group Stage'!$E$2:$E$73='Group Stage'!$F$2:$F$73))*1+ (('Group Stage'!$D$2:$D$73=A26)*('Group Stage'!$F$2:$F$73='Group Stage'!$E$2:$E$73))*1 )} -> 9 | Q26: {=SUMPRODUCT( ('Group Stage'!$C$2:$C$73=A26)*('Group Stage'!$E$2:$E$73-'Group Stage'!$F$2:$F$73)+ ('Group Stage'!$D$2:$D$73=A26)*('Group Stage'!$F$2:$F$73-'Group Stage'!$E$2:$E$73) )} -> 6 | R26: {=SUMPRODUCT( ('Group Stage'!$C$2:$C$73=A26)*'Group Stage'!$E$2:$E$73+ ('Group Stage'!$D$2:$D$73=A26)*'Group Stage'!$F$2:$F$73 )} -> 6 | S26: {=SUMPRODUCT( (('Elimination Rounds'!$L$2:$L$49=L26)* (('Elimination Rounds'!$P$2:$P$49>P26)+ ('Elimination Rounds'!$P$2:$P$49=P26)*('Elimination Rounds'!$Q$2:$Q$49>Q26)+ ('Elimination Rounds'!$P$2:$P$49=P26)*('Elimination Rounds'!$Q$2:$Q$49=Q26)*('Elimination Rounds'!$R$2:$R$49>R26))) )+1} -> 1 | U26: Belgium | V26: G | W26: 3 | X26: 0 | Y26: 0 | Z26: 9 | AA26: 6 | AB26: 6 | AC26: 1 | AF26: =U18 -> Germany | AG26: =V18 -> E | AH26: =W18 -> 3 | AI26: =X18 -> 0 | AJ26: =Y18 -> 0 | AK26: =Z18 -> 9 | AL26: =AA18 -> 5 | AM26: =AB18 -> 5 | AN26: =AC18 -> 1
A27: Iran | B27: =C27&D27 -> G3 | C27: G | D27: 3 | K27: Iran | L27: G | M27: {=SUMPRODUCT( (('Group Stage'!$C$2:$C$73=A27)*('Group Stage'!$E$2:$E$73>'Group Stage'!$F$2:$F$73))+ (('Group Stage'!$D$2:$D$73=A27)*('Group Stage'!$F$2:$F$73>'Group Stage'!$E$2:$E$73)) )} -> 1 | N27: {=SUMPRODUCT( (('Group Stage'!$C$2:$C$73=A27)*('Group Stage'!$E$2:$E$73='Group Stage'!$F$2:$F$73))+ (('Group Stage'!$D$2:$D$73=A27)*('Group Stage'!$F$2:$F$73='Group Stage'!$E$2:$E$73)) )} -> 0 | O27: {=SUMPRODUCT( (('Group Stage'!$C$2:$C$73=A27)*('Group Stage'!$E$2:$E$73<'Group Stage'!$F$2:$F$73))+ (('Group Stage'!$D$2:$D$73=A27)*('Group Stage'!$F$2:$F$73<'Group Stage'!$E$2:$E$73)) )} -> 2 | P27: {=SUMPRODUCT( (('Group Stage'!$C$2:$C$73=A27)*('Group Stage'!$E$2:$E$73>'Group Stage'!$F$2:$F$73))*3+ (('Group Stage'!$D$2:$D$73=A27)*('Group Stage'!$F$2:$F$73>'Group Stage'!$E$2:$E$73))*3+ (('Group Stage'!$C$2:$C$73=A27)*('Group Stage'!$E$2:$E$73='Group Stage'!$F$2:$F$73))*1+ (('Group Stage'!$D$2:$D$73=A27)*('Group Stage'!$F$2:$F$73='Group Stage'!$E$2:$E$73))*1 )} -> 3 | Q27: {=SUMPRODUCT( ('Group Stage'!$C$2:$C$73=A27)*('Group Stage'!$E$2:$E$73-'Group Stage'!$F$2:$F$73)+ ('Group Stage'!$D$2:$D$73=A27)*('Group Stage'!$F$2:$F$73-'Group Stage'!$E$2:$E$73) )} -> -2 | R27: {=SUMPRODUCT( ('Group Stage'!$C$2:$C$73=A27)*'Group Stage'!$E$2:$E$73+ ('Group Stage'!$D$2:$D$73=A27)*'Group Stage'!$F$2:$F$73 )} -> 1 | S27: {=SUMPRODUCT( (('Elimination Rounds'!$L$2:$L$49=L27)* (('Elimination Rounds'!$P$2:$P$49>P27)+ ('Elimination Rounds'!$P$2:$P$49=P27)*('Elimination Rounds'!$Q$2:$Q$49>Q27)+ ('Elimination Rounds'!$P$2:$P$49=P27)*('Elimination Rounds'!$Q$2:$Q$49=Q27)*('Elimination Rounds'!$R$2:$R$49>R27))) )+1} -> 3 | U27: Egypt | V27: G | W27: 2 | X27: 0 | Y27: 1 | Z27: 6 | AA27: 0 | AB27: 2 | AC27: 2 | AF27: =U19 -> Ecuador | AG27: =V19 -> E | AH27: =W19 -> 1 | AI27: =X19 -> 1 | AJ27: =Y19 -> 1 | AK27: =Z19 -> 4 | AL27: =AA19 -> 1 | AM27: =AB19 -> 3 | AN27: =AC19 -> 2
A28: Egypt | B28: =C28&D28 -> G2 | C28: G | D28: 2 | K28: Egypt | L28: G | M28: {=SUMPRODUCT( (('Group Stage'!$C$2:$C$73=A28)*('Group Stage'!$E$2:$E$73>'Group Stage'!$F$2:$F$73))+ (('Group Stage'!$D$2:$D$73=A28)*('Group Stage'!$F$2:$F$73>'Group Stage'!$E$2:$E$73)) )} -> 2 | N28: {=SUMPRODUCT( (('Group Stage'!$C$2:$C$73=A28)*('Group Stage'!$E$2:$E$73='Group Stage'!$F$2:$F$73))+ (('Group Stage'!$D$2:$D$73=A28)*('Group Stage'!$F$2:$F$73='Group Stage'!$E$2:$E$73)) )} -> 0 | O28: {=SUMPRODUCT( (('Group Stage'!$C$2:$C$73=A28)*('Group Stage'!$E$2:$E$73<'Group Stage'!$F$2:$F$73))+ (('Group Stage'!$D$2:$D$73=A28)*('Group Stage'!$F$2:$F$73<'Group Stage'!$E$2:$E$73)) )} -> 1 | P28: {=SUMPRODUCT( (('Group Stage'!$C$2:$C$73=A28)*('Group Stage'!$E$2:$E$73>'Group Stage'!$F$2:$F$73))*3+ (('Group Stage'!$D$2:$D$73=A28)*('Group Stage'!$F$2:$F$73>'Group Stage'!$E$2:$E$73))*3+ (('Group Stage'!$C$2:$C$73=A28)*('Group Stage'!$E$2:$E$73='Group Stage'!$F$2:$F$73))*1+ (('Group Stage'!$D$2:$D$73=A28)*('Group Stage'!$F$2:$F$73='Group Stage'!$E$2:$E$73))*1 )} -> 6 | Q28: {=SUMPRODUCT( ('Group Stage'!$C$2:$C$73=A28)*('Group Stage'!$E$2:$E$73-'Group Stage'!$F$2:$F$73)+ ('Group Stage'!$D$2:$D$73=A28)*('Group Stage'!$F$2:$F$73-'Group Stage'!$E$2:$E$73) )} -> 0 | R28: {=SUMPRODUCT( ('Group Stage'!$C$2:$C$73=A28)*'Group Stage'!$E$2:$E$73+ ('Group Stage'!$D$2:$D$73=A28)*'Group Stage'!$F$2:$F$73 )} -> 2 | S28: {=SUMPRODUCT( (('Elimination Rounds'!$L$2:$L$49=L28)* (('Elimination Rounds'!$P$2:$P$49>P28)+ ('Elimination Rounds'!$P$2:$P$49=P28)*('Elimination Rounds'!$Q$2:$Q$49>Q28)+ ('Elimination Rounds'!$P$2:$P$49=P28)*('Elimination Rounds'!$Q$2:$Q$49=Q28)*('Elimination Rounds'!$R$2:$R$49>R28))) )+1} -> 2 | U28: Iran | V28: G | W28: 1 | X28: 0 | Y28: 2 | Z28: 3 | AA28: -2 | AB28: 1 | AC28: 3 | AF28: =U20 -> Ivory Coast | AG28: =V20 -> E | AH28: =W20 -> 1 | AI28: =X20 -> 1 | AJ28: =Y20 -> 1 | AK28: =Z20 -> 4 | AL28: =AA20 -> 0 | AM28: =AB20 -> 3 | AN28: =AC20 -> 3
