Workbook

Sheet Scoring Rules
A1: Outcome | B1: Points | C1: Potential points
A2: Correctly guessing Win/Loss/Draw of group game | B2: +1 | C2: 72
A3: Correctly guessing exact score of group game | B3: +2 | C3: 144
A4: Correctly picking group winner (A-L) | B4: +2 | C4: 24
A5: Correctly picking each non-winning group place | B5: +1 | C5: 36
A6: Correctly picking each team in Round of 16 | B6: +2 | C6: 32
A7: Correctly picking each team in Quarter-finals | B7: +4 | C7: 32
A8: Correctly picking each team in Semi-finals | B8: +8 | C8: 32
A9: Correctly picking each Final team | B9: +16 | C9: 32
A10: Correctly picking World Cup Winner | B10: +32 | C10: 32
A11: TOTAL | C11: =SUM(C2:C10) -> 436

Sheet Group Stage
A1: Match | B1: Group | C1: Home | D1: Away | E1: Home Goals | F1: Away Goals | G1: Result | I1: Self check
A2: 1 | B2: A | C2: Mexico | D2: South Korea | E2: 1 | F2: 0 | G2: =IF(AND(E2<>"",F2<>""),IF(E2>F2,C2,IF(E2<F2,D2,"Draw")),"") -> Mexico | I2: Home | J2: {=SUMPRODUCT((G2:G73=C2:C73)*1)} -> 50
A3: 2 | B3: A | C3: South Africa | D3: Czechia | E3: 2 | F3: 0 | G3: =IF(AND(E3<>"",F3<>""),IF(E3>F3,C3,IF(E3<F3,D3,"Draw")),"") -> South Africa | I3: Away | J3: {=SUMPRODUCT((G2:G73=D2:D73)*1)} -> 13
A4: 3 | B4: A | C4: Mexico | D4: South Africa | E4: 2 | F4: 0 | G4: =IF(AND(E4<>"",F4<>""),IF(E4>F4,C4,IF(E4<F4,D4,"Draw")),"") -> Mexico | I4: Draw | J4: =COUNTIF(G2:G73,"Draw") -> 9
A5: 4 | B5: A | C5: South Korea | D5: Czechia | E5: 1 | F5: 0 | G5: =IF(AND(E5<>"",F5<>""),IF(E5>F5,C5,IF(E5<F5,D5,"Draw")),"") -> South Korea | I5: TOTAL | J5: =SUM(J2:J4) -> 72
A6: 5 | B6: A | C6: Mexico | D6: Czechia | E6: 3 | F6: 0 | G6: =IF(AND(E6<>"",F6<>""),IF(E6>F6,C6,IF(E6<F6,D6,"Draw")),"") -> Mexico | I6: (should total 72)
A7: 6 | B7: A | C7: South Korea | D7: South Africa | E7: 2 | F7: 1 | G7: =IF(AND(E7<>"",F7<>""),IF(E7>F7,C7,IF(E7<F7,D7,"Draw")),"") -> South Korea
A8: 7 | B8: B | C8: Canada | D8: Switzerland | E8: 0 | F8: 3 | G8: =IF(AND(E8<>"",F8<>""),IF(E8>F8,C8,IF(E8<F8,D8,"Draw")),"") -> Switzerland
A9: 8 | B9: B | C9: Qatar | D9: Bosnia-Herzegovina | E9: 0 | F9: 2 | G9: =IF(AND(E9<>"",F9<>""),IF(E9>F9,C9,IF(E9<F9,D9,"Draw")),"") -> Bosnia-Herzegovina
A10: 9 | B10: B | C10: Canada | D10: Qatar | E10: 1 | F10: 0 | G10: =IF(AND(E10<>"",F10<>""),IF(E10>F10,C10,IF(E10<F10,D10,"Draw")),"") -> Canada
A11: 10 | B11: B | C11: Switzerland | D11: Bosnia-Herzegovina | E11: 1 | F11: 0 | G11: =IF(AND(E11<>"",F11<>""),IF(E11>F11,C11,IF(E11<F11,D11,"Draw")),"") -> Switzerland
A12: 11 | B12: B | C12: Canada | D12: Bosnia-Herzegovina | E12: 1 | F12: 1 | G12: =IF(AND(E12<>"",F12<>""),IF(E12>F12,C12,IF(E12<F12,D12,"Draw")),"") -> Draw
A13: 12 | B13: B | C13: Switzerland | D13: Qatar | E13: 3 | F13: 0 | G13: =IF(AND(E13<>"",F13<>""),IF(E13>F13,C13,IF(E13<F13,D13,"Draw")),"") -> Switzerland
A14: 13 | B14: C | C14: Brazil | D14: Morocco | E14: 2 | F14: 1 | G14: =IF(AND(E14<>"",F14<>""),IF(E14>F14,C14,IF(E14<F14,D14,"Draw")),"") -> Brazil
A15: 14 | B15: C | C15: Scotland | D15: Haiti | E15: 3 | F15: 0 | G15: =IF(AND(E15<>"",F15<>""),IF(E15>F15,C15,IF(E15<F15,D15,"Draw")),"") -> Scotland
A16: 15 | B16: C | C16: Brazil | D16: Scotland | E16: 3 | F16: 0 | G16: =IF(AND(E16<>"",F16<>""),IF(E16>F16,C16,IF(E16<F16,D16,"Draw")),"") -> Brazil
A17: 16 | B17: C | C17: Morocco | D17: Haiti | E17: 1 | F17: 0 | G17: =IF(AND(E17<>"",F17<>""),IF(E17>F17,C17,IF(E17<F17,D17,"Draw")),"") -> Morocco
A18: 17 | B18: C | C18: Brazil | D18: Haiti | E18: 3 | F18: 0 | G18: =IF(AND(E18<>"",F18<>""),IF(E18>F18,C18,IF(E18<F18,D18,"Draw")),"") -> Brazil
... A73: 72 | B73: L | C73: Croatia | D73: Panama | E73: 2 | F73: 0 | G73: =IF(AND(E73<>"",F73<>""),IF(E73>F73,C73,IF(E73<F73,D73,"Draw")),"") -> Croatia

Sheet Elimination Rounds
A1: Team | B1: Code | C1: Group | D1: Group Finish (1-4) | E1: Round of 16 | F1: Quarter-finals | G1: Semi-finals | H1: Final | I1: Winner
A2: Mexico | B2: =C2&D2 -> A1 | C2: A | D2: 1 | E2: 1
A3: South Korea | B3: =C3&D3 -> A2 | C3: A | D3: 2
A4: South Africa | B4: =C4&D4 -> A3 | C4: A | D4: 3
A5: Czechia | B5: =C5&D5 -> A4 | C5: A | D5: 4
A6: Canada | B6: =C6&D6 -> B3 | C6: B | D6: 3
A7: Switzerland | B7: =C7&D7 -> B1 | C7: B | D7: 1 | E7: 1
A8: Qatar | B8: =C8&D8 -> B4 | C8: B | D8: 4
A9: Bosnia-Herzegovina | B9: =C9&D9 -> B2 | C9: B | D9: 2
A10: Brazil | B10: =C10&D10 -> C1 | C10: C | D10: 1 | E10: 1 | F10: 1 | G10: 1
A11: Morocco | B11: =C11&D11 -> C3 | C11: C | D11: 3
A12: Scotland | B12: =C12&D12 -> C2 | C12: C | D12: 2
A13: Haiti | B13: =C13&D13 -> C4 | C13: C | D13: 4
A14: USA | B14: =C14&D14 -> D3 | C14: D | D14: 3
A15: Paraguay | B15: =C15&D15 -> D4 | C15: D | D15: 4
A16: Australia | B16: =C16&D16 -> D2 | C16: D | D16: 2
A17: Turkiye | B17: =C17&D17 -> D1 | C17: D | D17: 1 | E17: 1
A18: Germany | B18: =C18&D18 -> E1 | C18: E | D18: 1 | E18: 1 | F18: 1
A19: Ecuador | B19: =C19&D19 -> E3 | C19: E | D19: 3
A20: Ivory Coast | B20: =C20&D20 -> E2 | C20: E | D20: 2 | E20: 1
A21: Curacao | B21: =C21&D21 -> E4 | C21: E | D21: 4
A22: Netherlands | B22: =C22&D22 -> F1 | C22: F | D22: 1
A23: Japan | B23: =C23&D23 -> F3 | C23: F | D23: 3 | E23: 1
A24: Tunisia | B24: =C24&D24 -> F4 | C24: F | D24: 4
A25: Sweden | B25: =C25&D25 -> F2 | C25: F | D25: 2 | E25: 1
A26: Belgium | B26: =C26&D26 -> G1 | C26: G | D26: 1 | E26: 1 | F26: 1
A27: Iran | B27: =C27&D27 -> G4 | C27: G | D27: 4
A28: Egypt | B28: =C28&D28 -> G2 | C28: G | D28: 2
A29: New Zealand | B29: =C29&D29 -> G3 | C29: G | D29: 3
A30: Spain | B30: =C30&D30 -> H1 | C30: H | D30: 1 | E30: 1 | F30: 1 | G30: 1 | H30: 1 | I30: 1
A31: Uruguay | B31: =C31&D31 -> H2 | C31: H | D31: 2
A32: Saudi Arabia | B32: =C32&D32 -> H3 | C32: H | D32: 3
A33: Cape Verde | B33: =C33&D33 -> H4 | C33: H | D33: 4
A34: France | B34: =C34&D34 -> I1 | C34: I | D34: 1 | E34: 1 | F34: 1
A35: Senegal | B35: =C35&D35 -> I3 | C35: I | D35: 3
A36: Norway | B36: =C36&D36 -> I2 | C36: I | D36: 2 | E36: 1
A37: Iraq | B37: =C37&D37 -> I4 | C37: I | D37: 4
A38: Argentina | B38: =C38&D38 -> J1 | C38: J | D38: 1 | E38: 1 | F38: 1
A39: Austria | B39: =C39&D39 -> J2 | C39: J | D39: 2
A40: Algeria | B40: =C40&D40 -> J3 | C40: J | D40: 3
...

Sheet Checks
A1: GROUP CHECK | B1: 1 | C1: 2 | D1: 3 | E1: 4 | G1: STAGE COUNT CHECK | H1: STATUS
A2: A | B2: {=IF(ISNA(MATCH($A2&B$1,'Elimination Rounds'!$B$2:$B$49,0)),"Choice not made!",INDEX('Elimination Rounds'!$A$2:$A$49,MATCH($A2&B$1,'Elimination Rounds'!$B$2:$B$49,0)))} -> Mexico | C2: {=IF(ISNA(MATCH($A2&C$1,'Elimination Rounds'!$B$2:$B$49,0)),"Choice not made!",INDEX('Elimination Rounds'!$A$2:$A$49,MATCH($A2&C$1,'Elimination Rounds'!$B$2:$B$49,0)))} -> South Korea | D2: {=IF(ISNA(MATCH($A2&D$1,'Elimination Rounds'!$B$2:$B$49,0)),"Choice not made!",INDEX('Elimination Rounds'!$A$2:$A$49,MATCH($A2&D$1,'Elimination Rounds'!$B$2:$B$49,0)))} -> South Africa | E2: {=IF(ISNA(MATCH($A2&E$1,'Elimination Rounds'!$B$2:$B$49,0)),"Choice not made!",INDEX('Elimination Rounds'!$A$2:$A$49,MATCH($A2&E$1,'Elimination Rounds'!$B$2:$B$49,0)))} -> Czechia | G2: ROUND OF 16 | H2: =IF(SUM('Elimination Rounds'!E2:E49)=16,"OK","DID NOT SELECT CORRECT NUMBER") -> OK | I2: :16
A3: B | B3: {=IF(ISNA(MATCH($A3&B$1,'Elimination Rounds'!$B$2:$B$49,0)),"Choice not made!",INDEX('Elimination Rounds'!$A$2:$A$49,MATCH($A3&B$1,'Elimination Rounds'!$B$2:$B$49,0)))} -> Switzerland | C3: {=IF(ISNA(MATCH($A3&C$1,'Elimination Rounds'!$B$2:$B$49,0)),"Choice not made!",INDEX('Elimination Rounds'!$A$2:$A$49,MATCH($A3&C$1,'Elimination Rounds'!$B$2:$B$49,0)))} -> Bosnia-Herzegovina | D3: {=IF(ISNA(MATCH($A3&D$1,'Elimination Rounds'!$B$2:$B$49,0)),"Choice not made!",INDEX('Elimination Rounds'!$A$2:$A$49,MATCH($A3&D$1,'Elimination Rounds'!$B$2:$B$49,0)))} -> Canada | E3: {=IF(ISNA(MATCH($A3&E$1,'Elimination Rounds'!$B$2:$B$49,0)),"Choice not made!",INDEX('Elimination Rounds'!$A$2:$A$49,MATCH($A3&E$1,'Elimination Rounds'!$B$2:$B$49,0)))} -> Qatar | G3: QUARTER-FINALS | H3: =IF(SUM('Elimination Rounds'!F2:F49)=8,"OK","DID NOT SELECT CORRECT NUMBER") -> OK | I3: :8
A4: C | B4: {=IF(ISNA(MATCH($A4&B$1,'Elimination Rounds'!$B$2:$B$49,0)),"Choice not made!",INDEX('Elimination Rounds'!$A$2:$A$49,MATCH($A4&B$1,'Elimination Rounds'!$B$2:$B$49,0)))} -> Brazil | C4: {=IF(ISNA(MATCH($A4&C$1,'Elimination Rounds'!$B$2:$B$49,0)),"Choice not made!",INDEX('Elimination Rounds'!$A$2:$A$49,MATCH($A4&C$1,'Elimination Rounds'!$B$2:$B$49,0)))} -> Scotland | D4: {=IF(ISNA(MATCH($A4&D$1,'Elimination Rounds'!$B$2:$B$49,0)),"Choice not made!",INDEX('Elimination Rounds'!$A$2:$A$49,MATCH($A4&D$1,'Elimination Rounds'!$B$2:$B$49,0)))} -> Morocco | E4: {=IF(ISNA(MATCH($A4&E$1,'Elimination Rounds'!$B$2:$B$49,0)),"Choice not made!",INDEX('Elimination Rounds'!$A$2:$A$49,MATCH($A4&E$1,'Elimination Rounds'!$B$2:$B$49,0)))} -> Haiti | G4: SEMI-FINALS | H4: =IF(SUM('Elimination Rounds'!G2:G49)=4,"OK","DID NOT SELECT CORRECT NUMBER") -> OK | I4: :4
A5: D | B5: {=IF(ISNA(MATCH($A5&B$1,'Elimination Rounds'!$B$2:$B$49,0)),"Choice not made!",INDEX('Elimination Rounds'!$A$2:$A$49,MATCH($A5&B$1,'Elimination Rounds'!$B$2:$B$49,0)))} -> Turkiye | C5: {=IF(ISNA(MATCH($A5&C$1,'Elimination Rounds'!$B$2:$B$49,0)),"Choice not made!",INDEX('Elimination Rounds'!$A$2:$A$49,MATCH($A5&C$1,'Elimination Rounds'!$B$2:$B$49,0)))} -> Australia | D5: {=IF(ISNA(MATCH($A5&D$1,'Elimination Rounds'!$B$2:$B$49,0)),"Choice not made!",INDEX('Elimination Rounds'!$A$2:$A$49,MATCH($A5&D$1,'Elimination Rounds'!$B$2:$B$49,0)))} -> USA | E5: {=IF(ISNA(MATCH($A5&E$1,'Elimination Rounds'!$B$2:$B$49,0)),"Choice not made!",INDEX('Elimination Rounds'!$A$2:$A$49,MATCH($A5&E$1,'Elimination Rounds'!$B$2:$B$49,0)))} -> Paraguay | G5: FINAL | H5: =IF(SUM('Elimination Rounds'!H2:H49)=2,"OK","DID NOT SELECT CORRECT NUMBER") -> OK | I5: :2
A6: E | B6: {=IF(ISNA(MATCH($A6&B$1,'Elimination Rounds'!$B$2:$B$49,0)),"Choice not made!",INDEX('Elimination Rounds'!$A$2:$A$49,MATCH($A6&B$1,'Elimination Rounds'!$B$2:$B$49,0)))} -> Germany | C6: {=IF(ISNA(MATCH($A6&C$1,'Elimination Rounds'!$B$2:$B$49,0)),"Choice not made!",INDEX('Elimination Rounds'!$A$2:$A$49,MATCH($A6&C$1,'Elimination Rounds'!$B$2:$B$49,0)))} -> Ivory Coast | D6: {=IF(ISNA(MATCH($A6&D$1,'Elimination Rounds'!$B$2:$B$49,0)),"Choice not made!",INDEX('Elimination Rounds'!$A$2:$A$49,MATCH($A6&D$1,'Elimination Rounds'!$B$2:$B$49,0)))} -> Ecuador | E6: {=IF(ISNA(MATCH($A6&E$1,'Elimination Rounds'!$B$2:$B$49,0)),"Choice not made!",INDEX('Elimination Rounds'!$A$2:$A$49,MATCH($A6&E$1,'Elimination Rounds'!$B$2:$B$49,0)))} -> Curacao | G6: WINNER | H6: =IF(SUM('Elimination Rounds'!I2:I49)=1,"OK","DID NOT SELECT CORRECT NUMBER") -> OK | I6: :1
A7: F | B7: {=IF(ISNA(MATCH($A7&B$1,'Elimination Rounds'!$B$2:$B$49,0)),"Choice not made!",INDEX('Elimination Rounds'!$A$2:$A$49,MATCH($A7&B$1,'Elimination Rounds'!$B$2:$B$49,0)))} -> Netherlands | C7: {=IF(ISNA(MATCH($A7&C$1,'Elimination Rounds'!$B$2:$B$49,0)),"Choice not made!",INDEX('Elimination Rounds'!$A$2:$A$49,MATCH($A7&C$1,'Elimination Rounds'!$B$2:$B$49,0)))} -> Sweden | D7: {=IF(ISNA(MATCH($A7&D$1,'Elimination Rounds'!$B$2:$B$49,0)),"Choice not made!",INDEX('Elimination Rounds'!$A$2:$A$49,MATCH($A7&D$1,'Elimination Rounds'!$B$2:$B$49,0)))} -> Japan | E7: {=IF(ISNA(MATCH($A7&E$1,'Elimination Rounds'!$B$2:$B$49,0)),"Choice not made!",INDEX('Elimination Rounds'!$A$2:$A$49,MATCH($A7&E$1,'Elimination Rounds'!$B$2:$B$49,0)))} -> Tunisia
A8: G | B8: {=IF(ISNA(MATCH($A8&B$1,'Elimination Rounds'!$B$2:$B$49,0)),"Choice not made!",INDEX('Elimination Rounds'!$A$2:$A$49,MATCH($A8&B$1,'Elimination Rounds'!$B$2:$B$49,0)))} -> Belgium | C8: {=IF(ISNA(MATCH($A8&C$1,'Elimination Rounds'!$B$2:$B$49,0)),"Choice not made!",INDEX('Elimination Rounds'!$A$2:$A$49,MATCH($A8&C$1,'Elimination Rounds'!$B$2:$B$49,0)))} -> Egypt | D8: {=IF(ISNA(MATCH($A8&D$1,'Elimination Rounds'!$B$2:$B$49,0)),"Choice not made!",INDEX('Elimination Rounds'!$A$2:$A$49,MATCH($A8&D$1,'Elimination Rounds'!$B$2:$B$49,0)))} -> New Zealand | E8: {=IF(ISNA(MATCH($A8&E$1,'Elimination Rounds'!$B$2:$B$49,0)),"Choice not made!",INDEX('Elimination Rounds'!$A$2:$A$49,MATCH($A8&E$1,'Elimination Rounds'!$B$2:$B$49,0)))} -> Iran | G8: GROUP STAGE GAMES CHECK | H8: STATUS
A9: H | B9: {=IF(ISNA(MATCH($A9&B$1,'Elimination Rounds'!$B$2:$B$49,0)),"Choice not made!",INDEX('Elimination Rounds'!$A$2:$A$49,MATCH($A9&B$1,'Elimination Rounds'!$B$2:$B$49,0)))} -> Spain | C9: {=IF(ISNA(MATCH($A9&C$1,'Elimination Rounds'!$B$2:$B$49,0)),"Choice not made!",INDEX('Elimination Rounds'!$A$2:$A$49,MATCH($A9&C$1,'Elimination Rounds'!$B$2:$B$49,0)))} -> Uruguay | D9: {=IF(ISNA(MATCH($A9&D$1,'Elimination Rounds'!$B$2:$B$49,0)),"Choice not made!",INDEX('Elimination Rounds'!$A$2:$A$49,MATCH($A9&D$1,'Elimination Rounds'!$B$2:$B$49,0)))} -> Saudi Arabia | E9: {=IF(ISNA(MATCH($A9&E$1,'Elimination Rounds'!$B$2:$B$49,0)),"Choice not made!",INDEX('Elimination Rounds'!$A$2:$A$49,MATCH($A9&E$1,'Elimination Rounds'!$B$2:$B$49,0)))} -> Cape Verde | G9: GAMES PICKED | H9: =IF('Group Stage'!J5=72,"GOOD TO GO!","SOME GAMES NOT PICKED") -> GOOD TO GO!
A10: I | B10: {=IF(ISNA(MATCH($A10&B$1,'Elimination Rounds'!$B$2:$B$49,0)),"Choice not made!",INDEX('Elimination Rounds'!$A$2:$A$49,MATCH($A10&B$1,'Elimination Rounds'!$B$2:$B$49,0)))} -> France | C10: {=IF(ISNA(MATCH($A10&C$1,'Elimination Rounds'!$B$2:$B$49,0)),"Choice not made!",INDEX('Elimination Rounds'!$A$2:$A$49,MATCH($A10&C$1,'Elimination Rounds'!$B$2:$B$49,0)))} -> Norway | D10: {=IF(ISNA(MATCH($A10&D$1,'Elimination Rounds'!$B$2:$B$49,0)),"Choice not made!",INDEX('Elimination Rounds'!$A$2:$A$49,MATCH($A10&D$1,'Elimination Rounds'!$B$2:$B$49,0)))} -> Senegal | E10: {=IF(ISNA(MATCH($A10&E$1,'Elimination Rounds'!$B$2:$B$49,0)),"Choice not made!",INDEX('Elimination Rounds'!$A$2:$A$49,MATCH($A10&E$1,'Elimination Rounds'!$B$2:$B$49,0)))} -> Iraq
A11: J | B11: {=IF(ISNA(MATCH($A11&B$1,'Elimination Rounds'!$B$2:$B$49,0)),"Choice not made!",INDEX('Elimination Rounds'!$A$2:$A$49,MATCH($A11&B$1,'Elimination Rounds'!$B$2:$B$49,0)))} -> Argentina | C11: {=IF(ISNA(MATCH($A11&C$1,'Elimination Rounds'!$B$2:$B$49,0)),"Choice not made!",INDEX('Elimination Rounds'!$A$2:$A$49,MATCH($A11&C$1,'Elimination Rounds'!$B$2:$B$49,0)))} -> Austria | D11: {=IF(ISNA(MATCH($A11&D$1,'Elimination Rounds'!$B$2:$B$49,0)),"Choice not made!",INDEX('Elimination Rounds'!$A$2:$A$49,MATCH($A11&D$1,'Elimination Rounds'!$B$2:$B$49,0)))} -> Algeria | E11: {=IF(ISNA(MATCH($A11&E$1,'Elimination Rounds'!$B$2:$B$49,0)),"Choice not made!",INDEX('Elimination Rounds'!$A$2:$A$49,MATCH($A11&E$1,'Elimination Rounds'!$B$2:$B$49,0)))} -> Jordan
A12: K | B12: {=IF(ISNA(MATCH($A12&B$1,'Elimination Rounds'!$B$2:$B$49,0)),"Choice not made!",INDEX('Elimination Rounds'!$A$2:$A$49,MATCH($A12&B$1,'Elimination Rounds'!$B$2:$B$49,0)))} -> Portugal | C12: {=IF(ISNA(MATCH($A12&C$1,'Elimination Rounds'!$B$2:$B$49,0)),"Choice not made!",INDEX('Elimination Rounds'!$A$2:$A$49,MATCH($A12&C$1,'Elimination Rounds'!$B$2:$B$49,0)))} -> Colombia | D12: {=IF(ISNA(MATCH($A12&D$1,'Elimination Rounds'!$B$2:$B$49,0)),"Choice not made!",INDEX('Elimination Rounds'!$A$2:$A$49,MATCH($A12&D$1,'Elimination Rounds'!$B$2:$B$49,0)))} -> DR Congo | E12: {=IF(ISNA(MATCH($A12&E$1,'Elimination Rounds'!$B$2:$B$49,0)),"Choice not made!",INDEX('Elimination Rounds'!$A$2:$A$49,MATCH($A12&E$1,'Elimination Rounds'!$B$2:$B$49,0)))} -> Uzbekistan
A13: L | B13: {=IF(ISNA(MATCH($A13&B$1,'Elimination Rounds'!$B$2:$B$49,0)),"Choice not made!",INDEX('Elimination Rounds'!$A$2:$A$49,MATCH($A13&B$1,'Elimination Rounds'!$B$2:$B$49,0)))} -> England | C13: {=IF(ISNA(MATCH($A13&C$1,'Elimination Rounds'!$B$2:$B$49,0)),"Choice not made!",INDEX('Elimination Rounds'!$A$2:$A$49,MATCH($A13&C$1,'Elimination Rounds'!$B$2:$B$49,0)))} -> Ghana | D13: {=IF(ISNA(MATCH($A13&D$1,'Elimination Rounds'!$B$2:$B$49,0)),"Choice not made!",INDEX('Elimination Rounds'!$A$2:$A$49,MATCH($A13&D$1,'Elimination Rounds'!$B$2:$B$49,0)))} -> Croatia | E13: {=IF(ISNA(MATCH($A13&E$1,'Elimination Rounds'!$B$2:$B$49,0)),"Choice not made!",INDEX('Elimination Rounds'!$A$2:$A$49,MATCH($A13&E$1,'Elimination Rounds'!$B$2:$B$49,0)))} -> Panama
A16: TOTAL ERRORS | B16: =COUNTIF(B2:E13,"Choice not made!")+COUNTIF(H2:H6,"DID NOT SELECT CORRECT NUMBER") -> 0
A18: =IF(B16=0,"GOOD TO GO!","NOT READY TO SUBMIT (SEE ERRORS ABOVE)") -> GOOD TO GO!
