Workbook

Sheet Scoring Rules
A1: Outcome | B1: Points | C1: Potential points
A2: Correctly guessing Win/Loss/Draw of group game | B2: +1 | C2: 72
A3: Correctly guessing exact score of group game | B3: +2 | C3: 144
A4: Correctly picking group winner (A-L) | B4: +2 | C4: 24
A5: Correctly picking each non-winning group place | B5: +1 | C5: 36
A6: Correctly picking each team in Round of 16 | B6: +2 | C6: 32
A7: Correctly picking each team in Quarter-finals | B7: +4 | C7: 32
A8: Correctly picking each team in Semi-finals | B8: +8 | C8: 32
A9: Correctly picking each Final team | B9: +16 | C9: 32
A10: Correctly picking World Cup Winner | B10: +32 | C10: 32
A11: TOTAL | C11: =SUM(C2:C10)

Sheet Group Stage
A1: Match | B1: Group | C1: Home | D1: Away | E1: Home Goals | F1: Away Goals | G1: Result | I1: Self check
A2: 1 | B2: A | C2: Mexico | D2: South Korea | E2: 2 | F2: 1 | G2: =IF(AND(E2<>"",F2<>""),IF(E2>F2,C2,IF(E2<F2,D2,"Draw")),"") | I2: Home | J2: {=SUMPRODUCT((G2:G73=C2:C73)*1)}
A3: 2 | B3: A | C3: South Africa | D3: Czechia | E3: 2 | F3: 1 | G3: =IF(AND(E3<>"",F3<>""),IF(E3>F3,C3,IF(E3<F3,D3,"Draw")),"") | I3: Away | J3: {=SUMPRODUCT((G2:G73=D2:D73)*1)}
A4: 3 | B4: A | C4: Mexico | D4: South Africa | E4: 2 | F4: 2 | G4: =IF(AND(E4<>"",F4<>""),IF(E4>F4,C4,IF(E4<F4,D4,"Draw")),"") | I4: Draw | J4: =COUNTIF(G2:G73,"Draw")
A5: 4 | B5: A | C5: South Korea | D5: Czechia | E5: 2 | F5: 1 | G5: =IF(AND(E5<>"",F5<>""),IF(E5>F5,C5,IF(E5<F5,D5,"Draw")),"") | I5: TOTAL | J5: =SUM(J2:J4)
A6: 5 | B6: A | C6: Mexico | D6: Czechia | E6: 1 | F6: 0 | G6: =IF(AND(E6<>"",F6<>""),IF(E6>F6,C6,IF(E6<F6,D6,"Draw")),"") | I6: (should total 72)
A7: 6 | B7: A | C7: South Korea | D7: South Africa | E7: 1 | F7: 1 | G7: =IF(AND(E7<>"",F7<>""),IF(E7>F7,C7,IF(E7<F7,D7,"Draw")),"")
A8: 7 | B8: B | C8: Canada | D8: Switzerland | E8: 1 | F8: 2 | G8: =IF(AND(E8<>"",F8<>""),IF(E8>F8,C8,IF(E8<F8,D8,"Draw")),"")
A9: 8 | B9: B | C9: Qatar | D9: Bosnia-Herzegovina | E9: 1 | F9: 1 | G9: =IF(AND(E9<>"",F9<>""),IF(E9>F9,C9,IF(E9<F9,D9,"Draw")),"")
A10: 9 | B10: B | C10: Canada | D10: Qatar | E10: 1 | F10: 1 | G10: =IF(AND(E10<>"",F10<>""),IF(E10>F10,C10,IF(E10<F10,D10,"Draw")),"")
A11: 10 | B11: B | C11: Switzerland | D11: Bosnia-Herzegovina | E11: 2 | F11: 1 | G11: =IF(AND(E11<>"",F11<>""),IF(E11>F11,C11,IF(E11<F11,D11,"Draw")),"")
A12: 11 | B12: B | C12: Canada | D12: Bosnia-Herzegovina | E12: 2 | F12: 1 | G12: =IF(AND(E12<>"",F12<>""),IF(E12>F12,C12,IF(E12<F12,D12,"Draw")),"")
A13: 12 | B13: B | C13: Switzerland | D13: Qatar | E13: 1 | F13: 0 | G13: =IF(AND(E13<>"",F13<>""),IF(E13>F13,C13,IF(E13<F13,D13,"Draw")),"")
A14: 13 | B14: C | C14: Brazil | D14: Morocco | E14: 2 | F14: 1 | G14: =IF(AND(E14<>"",F14<>""),IF(E14>F14,C14,IF(E14<F14,D14,"Draw")),"")
A15: 14 | B15: C | C15: Scotland | D15: Haiti | E15: 2 | F15: 0 | G15: =IF(AND(E15<>"",F15<>""),IF(E15>F15,C15,IF(E15<F15,D15,"Draw")),"")
A16: 15 | B16: C | C16: Brazil | D16: Scotland | E16: 1 | F16: 0 | G16: =IF(AND(E16<>"",F16<>""),IF(E16>F16,C16,IF(E16<F16,D16,"Draw")),"")
A17: 16 | B17: C | C17: Morocco | D17: Haiti | E17: 1 | F17: 0 | G17: =IF(AND(E17<>"",F17<>""),IF(E17>F17,C17,IF(E17<F17,D17,"Draw")),"")
A18: 17 | B18: C | C18: Brazil | D18: Haiti | E18: 2 | F18: 0 | G18: =IF(AND(E18<>"",F18<>""),IF(E18>F18,C18,IF(E18<F18,D18,"Draw")),"")
... A73: 72 | B73: L | C73: Croatia | D73: Panama | E73: 1 | F73: 0 | G73: =IF(AND(E73<>"",F73<>""),IF(E73>F73,C73,IF(E73<F73,D73,"Draw")),"")

Sheet Elimination Rounds
A1: Team | B1: Code | C1: Group | D1: Group Finish (1-4) | E1: Round of 16 | F1: Quarter-finals | G1: Semi-finals | H1: Final | I1: Winner
A2: Mexico | B2: =C2&D2 | C2: A | D2: 1 | E2: 1
A3: South Korea | B3: =C3&D3 | C3: A | D3: 2 | E3: 1
A4: South Africa | B4: =C4&D4 | C4: A | D4: 3
A5: Czechia | B5: =C5&D5 | C5: A | D5: 4
A6: Canada | B6: =C6&D6 | C6: B | D6: 2
A7: Switzerland | B7: =C7&D7 | C7: B | D7: 1 | E7: 1
A8: Qatar | B8: =C8&D8 | C8: B | D8: 4
A9: Bosnia-Herzegovina | B9: =C9&D9 | C9: B | D9: 3
A10: Brazil | B10: =C10&D10 | C10: C | D10: 1 | E10: 1 | F10: 1
A11: Morocco | B11: =C11&D11 | C11: C | D11: 2 | E11: 1
A12: Scotland | B12: =C12&D12 | C12: C | D12: 3
A13: Haiti | B13: =C13&D13 | C13: C | D13: 4
A14: USA | B14: =C14&D14 | C14: D | D14: 1 | E14: 1
A15: Paraguay | B15: =C15&D15 | C15: D | D15: 4
A16: Australia | B16: =C16&D16 | C16: D | D16: 2
A17: Turkiye | B17: =C17&D17 | C17: D | D17: 3
A18: Germany | B18: =C18&D18 | C18: E | D18: 1 | E18: 1 | F18: 1
A19: Ecuador | B19: =C19&D19 | C19: E | D19: 3
A20: Ivory Coast | B20: =C20&D20 | C20: E | D20: 2
A21: Curacao | B21: =C21&D21 | C21: E | D21: 4
A22: Netherlands | B22: =C22&D22 | C22: F | D22: 1 | E22: 1 | F22: 1
A23: Japan | B23: =C23&D23 | C23: F | D23: 2
A24: Tunisia | B24: =C24&D24 | C24: F | D24: 4
A25: Sweden | B25: =C25&D25 | C25: F | D25: 3
A26: Belgium | B26: =C26&D26 | C26: G | D26: 1 | E26: 1
A27: Iran | B27: =C27&D27 | C27: G | D27: 3
A28: Egypt | B28: =C28&D28 | C28: G | D28: 2
A29: New Zealand | B29: =C29&D29 | C29: G | D29: 4
A30: Spain | B30: =C30&D30 | C30: H | D30: 1 | E30: 1 | F30: 1 | G30: 1 | H30: 1 | I30: 1
A31: Uruguay | B31: =C31&D31 | C31: H | D31: 2 | E31: 1
A32: Saudi Arabia | B32: =C32&D32 | C32: H | D32: 3
A33: Cape Verde | B33: =C33&D33 | C33: H | D33: 4
A34: France | B34: =C34&D34 | C34: I | D34: 1 | E34: 1 | F34: 1 | G34: 1 | H34: 1
A35: Senegal | B35: =C35&D35 | C35: I | D35: 2 | E35: 1
A36: Norway | B36: =C36&D36 | C36: I | D36: 3
A37: Iraq | B37: =C37&D37 | C37: I | D37: 4
A38: Argentina | B38: =C38&D38 | C38: J | D38: 1 | E38: 1 | F38: 1 | G38: 1
A39: Austria | B39: =C39&D39 | C39: J | D39: 2
A40: Algeria | B40: =C40&D40 | C40: J | D40: 3
...

Sheet Checks
A1: GROUP CHECK | B1: 1 | C1: 2 | D1: 3 | E1: 4 | G1: STAGE COUNT CHECK | H1: STATUS
A2: A | B2: =IF(ISNA(MATCH($A2&B$1,'Elimination Rounds'!$B$2:$B$49,0)),"Choice not made!",INDEX('Elimination Rounds'!$A$2:$A$49,MATCH($A2&B$1,'Elimination Rounds'!$B$2:$B$49,0))) | C2: =IF(ISNA(MATCH($A2&C$1,'Elimination Rounds'!$B$2:$B$49,0)),"Choice not made!",INDEX('Elimination Rounds'!$A$2:$A$49,MATCH($A2&C$1,'Elimination Rounds'!$B$2:$B$49,0))) | D2: =IF(ISNA(MATCH($A2&D$1,'Elimination Rounds'!$B$2:$B$49,0)),"Choice not made!",INDEX('Elimination Rounds'!$A$2:$A$49,MATCH($A2&D$1,'Elimination Rounds'!$B$2:$B$49,0))) | E2: =IF(ISNA(MATCH($A2&E$1,'Elimination Rounds'!$B$2:$B$49,0)),"Choice not made!",INDEX('Elimination Rounds'!$A$2:$A$49,MATCH($A2&E$1,'Elimination Rounds'!$B$2:$B$49,0))) | G2: ROUND OF 16 | H2: =IF(SUM('Elimination Rounds'!E2:E49)=16,"OK","DID NOT SELECT CORRECT NUMBER") | I2: :16
A3: B | B3: =IF(ISNA(MATCH($A3&B$1,'Elimination Rounds'!$B$2:$B$49,0)),"Choice not made!",INDEX('Elimination Rounds'!$A$2:$A$49,MATCH($A3&B$1,'Elimination Rounds'!$B$2:$B$49,0))) | C3: =IF(ISNA(MATCH($A3&C$1,'Elimination Rounds'!$B$2:$B$49,0)),"Choice not made!",INDEX('Elimination Rounds'!$A$2:$A$49,MATCH($A3&C$1,'Elimination Rounds'!$B$2:$B$49,0))) | D3: =IF(ISNA(MATCH($A3&D$1,'Elimination Rounds'!$B$2:$B$49,0)),"Choice not made!",INDEX('Elimination Rounds'!$A$2:$A$49,MATCH($A3&D$1,'Elimination Rounds'!$B$2:$B$49,0))) | E3: =IF(ISNA(MATCH($A3&E$1,'Elimination Rounds'!$B$2:$B$49,0)),"Choice not made!",INDEX('Elimination Rounds'!$A$2:$A$49,MATCH($A3&E$1,'Elimination Rounds'!$B$2:$B$49,0))) | G3: QUARTER-FINALS | H3: =IF(SUM('Elimination Rounds'!F2:F49)=8,"OK","DID NOT SELECT CORRECT NUMBER") | I3: :8
A4: C | B4: =IF(ISNA(MATCH($A4&B$1,'Elimination Rounds'!$B$2:$B$49,0)),"Choice not made!",INDEX('Elimination Rounds'!$A$2:$A$49,MATCH($A4&B$1,'Elimination Rounds'!$B$2:$B$49,0))) | C4: =IF(ISNA(MATCH($A4&C$1,'Elimination Rounds'!$B$2:$B$49,0)),"Choice not made!",INDEX('Elimination Rounds'!$A$2:$A$49,MATCH($A4&C$1,'Elimination Rounds'!$B$2:$B$49,0))) | D4: =IF(ISNA(MATCH($A4&D$1,'Elimination Rounds'!$B$2:$B$49,0)),"Choice not made!",INDEX('Elimination Rounds'!$A$2:$A$49,MATCH($A4&D$1,'Elimination Rounds'!$B$2:$B$49,0))) | E4: =IF(ISNA(MATCH($A4&E$1,'Elimination Rounds'!$B$2:$B$49,0)),"Choice not made!",INDEX('Elimination Rounds'!$A$2:$A$49,MATCH($A4&E$1,'Elimination Rounds'!$B$2:$B$49,0))) | G4: SEMI-FINALS | H4: =IF(SUM('Elimination Rounds'!G2:G49)=4,"OK","DID NOT SELECT CORRECT NUMBER") | I4: :4
A5: D | B5: =IF(ISNA(MATCH($A5&B$1,'Elimination Rounds'!$B$2:$B$49,0)),"Choice not made!",INDEX('Elimination Rounds'!$A$2:$A$49,MATCH($A5&B$1,'Elimination Rounds'!$B$2:$B$49,0))) | C5: =IF(ISNA(MATCH($A5&C$1,'Elimination Rounds'!$B$2:$B$49,0)),"Choice not made!",INDEX('Elimination Rounds'!$A$2:$A$49,MATCH($A5&C$1,'Elimination Rounds'!$B$2:$B$49,0))) | D5: =IF(ISNA(MATCH($A5&D$1,'Elimination Rounds'!$B$2:$B$49,0)),"Choice not made!",INDEX('Elimination Rounds'!$A$2:$A$49,MATCH($A5&D$1,'Elimination Rounds'!$B$2:$B$49,0))) | E5: =IF(ISNA(MATCH($A5&E$1,'Elimination Rounds'!$B$2:$B$49,0)),"Choice not made!",INDEX('Elimination Rounds'!$A$2:$A$49,MATCH($A5&E$1,'Elimination Rounds'!$B$2:$B$49,0))) | G5: FINAL | H5: =IF(SUM('Elimination Rounds'!H2:H49)=2,"OK","DID NOT SELECT CORRECT NUMBER") | I5: :2
A6: E | B6: =IF(ISNA(MATCH($A6&B$1,'Elimination Rounds'!$B$2:$B$49,0)),"Choice not made!",INDEX('Elimination Rounds'!$A$2:$A$49,MATCH($A6&B$1,'Elimination Rounds'!$B$2:$B$49,0))) | C6: =IF(ISNA(MATCH($A6&C$1,'Elimination Rounds'!$B$2:$B$49,0)),"Choice not made!",INDEX('Elimination Rounds'!$A$2:$A$49,MATCH($A6&C$1,'Elimination Rounds'!$B$2:$B$49,0))) | D6: =IF(ISNA(MATCH($A6&D$1,'Elimination Rounds'!$B$2:$B$49,0)),"Choice not made!",INDEX('Elimination Rounds'!$A$2:$A$49,MATCH($A6&D$1,'Elimination Rounds'!$B$2:$B$49,0))) | E6: =IF(ISNA(MATCH($A6&E$1,'Elimination Rounds'!$B$2:$B$49,0)),"Choice not made!",INDEX('Elimination Rounds'!$A$2:$A$49,MATCH($A6&E$1,'Elimination Rounds'!$B$2:$B$49,0))) | G6: WINNER | H6: =IF(SUM('Elimination Rounds'!I2:I49)=1,"OK","DID NOT SELECT CORRECT NUMBER") | I6: :1
A7: F | B7: =IF(ISNA(MATCH($A7&B$1,'Elimination Rounds'!$B$2:$B$49,0)),"Choice not made!",INDEX('Elimination Rounds'!$A$2:$A$49,MATCH($A7&B$1,'Elimination Rounds'!$B$2:$B$49,0))) | C7: =IF(ISNA(MATCH($A7&C$1,'Elimination Rounds'!$B$2:$B$49,0)),"Choice not made!",INDEX('Elimination Rounds'!$A$2:$A$49,MATCH($A7&C$1,'Elimination Rounds'!$B$2:$B$49,0))) | D7: =IF(ISNA(MATCH($A7&D$1,'Elimination Rounds'!$B$2:$B$49,0)),"Choice not made!",INDEX('Elimination Rounds'!$A$2:$A$49,MATCH($A7&D$1,'Elimination Rounds'!$B$2:$B$49,0))) | E7: =IF(ISNA(MATCH($A7&E$1,'Elimination Rounds'!$B$2:$B$49,0)),"Choice not made!",INDEX('Elimination Rounds'!$A$2:$A$49,MATCH($A7&E$1,'Elimination Rounds'!$B$2:$B$49,0)))
A8: G | B8: =IF(ISNA(MATCH($A8&B$1,'Elimination Rounds'!$B$2:$B$49,0)),"Choice not made!",INDEX('Elimination Rounds'!$A$2:$A$49,MATCH($A8&B$1,'Elimination Rounds'!$B$2:$B$49,0))) | C8: =IF(ISNA(MATCH($A8&C$1,'Elimination Rounds'!$B$2:$B$49,0)),"Choice not made!",INDEX('Elimination Rounds'!$A$2:$A$49,MATCH($A8&C$1,'Elimination Rounds'!$B$2:$B$49,0))) | D8: =IF(ISNA(MATCH($A8&D$1,'Elimination Rounds'!$B$2:$B$49,0)),"Choice not made!",INDEX('Elimination Rounds'!$A$2:$A$49,MATCH($A8&D$1,'Elimination Rounds'!$B$2:$B$49,0))) | E8: =IF(ISNA(MATCH($A8&E$1,'Elimination Rounds'!$B$2:$B$49,0)),"Choice not made!",INDEX('Elimination Rounds'!$A$2:$A$49,MATCH($A8&E$1,'Elimination Rounds'!$B$2:$B$49,0))) | G8: GROUP STAGE GAMES CHECK | H8: STATUS
A9: H | B9: =IF(ISNA(MATCH($A9&B$1,'Elimination Rounds'!$B$2:$B$49,0)),"Choice not made!",INDEX('Elimination Rounds'!$A$2:$A$49,MATCH($A9&B$1,'Elimination Rounds'!$B$2:$B$49,0))) | C9: =IF(ISNA(MATCH($A9&C$1,'Elimination Rounds'!$B$2:$B$49,0)),"Choice not made!",INDEX('Elimination Rounds'!$A$2:$A$49,MATCH($A9&C$1,'Elimination Rounds'!$B$2:$B$49,0))) | D9: =IF(ISNA(MATCH($A9&D$1,'Elimination Rounds'!$B$2:$B$49,0)),"Choice not made!",INDEX('Elimination Rounds'!$A$2:$A$49,MATCH($A9&D$1,'Elimination Rounds'!$B$2:$B$49,0))) | E9: =IF(ISNA(MATCH($A9&E$1,'Elimination Rounds'!$B$2:$B$49,0)),"Choice not made!",INDEX('Elimination Rounds'!$A$2:$A$49,MATCH($A9&E$1,'Elimination Rounds'!$B$2:$B$49,0))) | G9: GAMES PICKED | H9: =IF('Group Stage'!J5=72,"GOOD TO GO!","SOME GAMES NOT PICKED")
A10: I | B10: =IF(ISNA(MATCH($A10&B$1,'Elimination Rounds'!$B$2:$B$49,0)),"Choice not made!",INDEX('Elimination Rounds'!$A$2:$A$49,MATCH($A10&B$1,'Elimination Rounds'!$B$2:$B$49,0))) | C10: =IF(ISNA(MATCH($A10&C$1,'Elimination Rounds'!$B$2:$B$49,0)),"Choice not made!",INDEX('Elimination Rounds'!$A$2:$A$49,MATCH($A10&C$1,'Elimination Rounds'!$B$2:$B$49,0))) | D10: =IF(ISNA(MATCH($A10&D$1,'Elimination Rounds'!$B$2:$B$49,0)),"Choice not made!",INDEX('Elimination Rounds'!$A$2:$A$49,MATCH($A10&D$1,'Elimination Rounds'!$B$2:$B$49,0))) | E10: =IF(ISNA(MATCH($A10&E$1,'Elimination Rounds'!$B$2:$B$49,0)),"Choice not made!",INDEX('Elimination Rounds'!$A$2:$A$49,MATCH($A10&E$1,'Elimination Rounds'!$B$2:$B$49,0)))
A11: J | B11: =IF(ISNA(MATCH($A11&B$1,'Elimination Rounds'!$B$2:$B$49,0)),"Choice not made!",INDEX('Elimination Rounds'!$A$2:$A$49,MATCH($A11&B$1,'Elimination Rounds'!$B$2:$B$49,0))) | C11: =IF(ISNA(MATCH($A11&C$1,'Elimination Rounds'!$B$2:$B$49,0)),"Choice not made!",INDEX('Elimination Rounds'!$A$2:$A$49,MATCH($A11&C$1,'Elimination Rounds'!$B$2:$B$49,0))) | D11: =IF(ISNA(MATCH($A11&D$1,'Elimination Rounds'!$B$2:$B$49,0)),"Choice not made!",INDEX('Elimination Rounds'!$A$2:$A$49,MATCH($A11&D$1,'Elimination Rounds'!$B$2:$B$49,0))) | E11: =IF(ISNA(MATCH($A11&E$1,'Elimination Rounds'!$B$2:$B$49,0)),"Choice not made!",INDEX('Elimination Rounds'!$A$2:$A$49,MATCH($A11&E$1,'Elimination Rounds'!$B$2:$B$49,0)))
A12: K | B12: =IF(ISNA(MATCH($A12&B$1,'Elimination Rounds'!$B$2:$B$49,0)),"Choice not made!",INDEX('Elimination Rounds'!$A$2:$A$49,MATCH($A12&B$1,'Elimination Rounds'!$B$2:$B$49,0))) | C12: =IF(ISNA(MATCH($A12&C$1,'Elimination Rounds'!$B$2:$B$49,0)),"Choice not made!",INDEX('Elimination Rounds'!$A$2:$A$49,MATCH($A12&C$1,'Elimination Rounds'!$B$2:$B$49,0))) | D12: =IF(ISNA(MATCH($A12&D$1,'Elimination Rounds'!$B$2:$B$49,0)),"Choice not made!",INDEX('Elimination Rounds'!$A$2:$A$49,MATCH($A12&D$1,'Elimination Rounds'!$B$2:$B$49,0))) | E12: =IF(ISNA(MATCH($A12&E$1,'Elimination Rounds'!$B$2:$B$49,0)),"Choice not made!",INDEX('Elimination Rounds'!$A$2:$A$49,MATCH($A12&E$1,'Elimination Rounds'!$B$2:$B$49,0)))
A13: L | B13: =IF(ISNA(MATCH($A13&B$1,'Elimination Rounds'!$B$2:$B$49,0)),"Choice not made!",INDEX('Elimination Rounds'!$A$2:$A$49,MATCH($A13&B$1,'Elimination Rounds'!$B$2:$B$49,0))) | C13: =IF(ISNA(MATCH($A13&C$1,'Elimination Rounds'!$B$2:$B$49,0)),"Choice not made!",INDEX('Elimination Rounds'!$A$2:$A$49,MATCH($A13&C$1,'Elimination Rounds'!$B$2:$B$49,0))) | D13: =IF(ISNA(MATCH($A13&D$1,'Elimination Rounds'!$B$2:$B$49,0)),"Choice not made!",INDEX('Elimination Rounds'!$A$2:$A$49,MATCH($A13&D$1,'Elimination Rounds'!$B$2:$B$49,0))) | E13: =IF(ISNA(MATCH($A13&E$1,'Elimination Rounds'!$B$2:$B$49,0)),"Choice not made!",INDEX('Elimination Rounds'!$A$2:$A$49,MATCH($A13&E$1,'Elimination Rounds'!$B$2:$B$49,0)))
A16: TOTAL ERRORS | B16: =COUNTIF(B2:E13,"Choice not made!")+COUNTIF(H2:H6,"DID NOT SELECT CORRECT NUMBER")
A18: =IF(B16=0,"GOOD TO GO!","NOT READY TO SUBMIT (SEE ERRORS ABOVE)")
